  0%|          | 0/9 [00:00<?, ?it/s]100%|‚ñà‚ñà‚ñà‚ñà‚ñà‚ñà‚ñà‚ñà‚ñà‚ñà| 9/9 [00:00<00:00, 1070.16it/s]
  0%|          | 0/9 [00:00<?, ?it/s]100%|‚ñà‚ñà‚ñà‚ñà‚ñà‚ñà‚ñà‚ñà‚ñà‚ñà| 9/9 [00:00<00:00, 10603.58it/s]
  0%|          | 0/9 [00:00<?, ?it/s]100%|‚ñà‚ñà‚ñà‚ñà‚ñà‚ñà‚ñà‚ñà‚ñà‚ñà| 9/9 [00:00<00:00, 11151.77it/s]
  0%|          | 0/9 [00:00<?, ?it/s]100%|‚ñà‚ñà‚ñà‚ñà‚ñà‚ñà‚ñà‚ñà‚ñà‚ñà| 9/9 [00:00<00:00, 10925.83it/s]
  0%|          | 0/9 [00:00<?, ?it/s]100%|‚ñà‚ñà‚ñà‚ñà‚ñà‚ñà‚ñà‚ñà‚ñà‚ñà| 9/9 [00:00<00:00, 10932.16it/s]
  0%|          | 0/9 [00:00<?, ?it/s]100%|‚ñà‚ñà‚ñà‚ñà‚ñà‚ñà‚ñà‚ñà‚ñà‚ñà| 9/9 [00:00<00:00, 11073.26it/s]
  0%|          | 0/9 [00:00<?, ?it/s]100%|‚ñà‚ñà‚ñà‚ñà‚ñà‚ñà‚ñà‚ñà‚ñà‚ñà| 9/9 [00:00<00:00, 11231.40it/s]
  0%|          | 0/9 [00:00<?, ?it/s]100%|‚ñà‚ñà‚ñà‚ñà‚ñà‚ñà‚ñà‚ñà‚ñà‚ñà| 9/9 [00:00<00:00, 11011.88it/s]
  0%|          | 0/9 [00:00<?, ?it/s]100%|‚ñà‚ñà‚ñà‚ñà‚ñà‚ñà‚ñà‚ñà‚ñà‚ñà| 9/9 [00:00<00:00, 10919.51it/s]
  0%|          | 0/9 [00:00<?, ?it/s]100%|‚ñà‚ñà‚ñà‚ñà‚ñà‚ñà‚ñà‚ñà‚ñà‚ñà| 9/9 [00:00<00:00, 11231.40it/s]
/home/otto.tavares/public/iltbi/rxp2p-cycle/p2p-cycle-env/lib/python3.9/site-packages/torch/utils/data/dataloader.py:558: UserWarning: This DataLoader will create 4 worker processes in total. Our suggested max number of worker in current system is 1, which is smaller than what this DataLoader is going to create. Please be aware that excessive worker creation might get DataLoader running slow or even freeze, lower the worker number to avoid potential slowness/freeze if necessary.
  warnings.warn(_create_warning_msg(
  0%|          | 0/9 [00:00<?, ?it/s]100%|‚ñà‚ñà‚ñà‚ñà‚ñà‚ñà‚ñà‚ñà‚ñà‚ñà| 9/9 [00:00<00:00, 9843.22it/s]
  0%|          | 0/9 [00:00<?, ?it/s]100%|‚ñà‚ñà‚ñà‚ñà‚ñà‚ñà‚ñà‚ñà‚ñà‚ñà| 9/9 [00:00<00:00, 10751.56it/s]
  0%|          | 0/9 [00:00<?, ?it/s]100%|‚ñà‚ñà‚ñà‚ñà‚ñà‚ñà‚ñà‚ñà‚ñà‚ñà| 9/9 [00:00<00:00, 11261.56it/s]
  0%|          | 0/9 [00:00<?, ?it/s]100%|‚ñà‚ñà‚ñà‚ñà‚ñà‚ñà‚ñà‚ñà‚ñà‚ñà| 9/9 [00:00<00:00, 11053.80it/s]
  0%|          | 0/9 [00:00<?, ?it/s]100%|‚ñà‚ñà‚ñà‚ñà‚ñà‚ñà‚ñà‚ñà‚ñà‚ñà| 9/9 [00:00<00:00, 11102.57it/s]
  0%|          | 0/9 [00:00<?, ?it/s]100%|‚ñà‚ñà‚ñà‚ñà‚ñà‚ñà‚ñà‚ñà‚ñà‚ñà| 9/9 [00:00<00:00, 10932.16it/s]
  0%|          | 0/9 [00:00<?, ?it/s]100%|‚ñà‚ñà‚ñà‚ñà‚ñà‚ñà‚ñà‚ñà‚ñà‚ñà| 9/9 [00:00<00:00, 11281.75it/s]
  0%|          | 0/9 [00:00<?, ?it/s]100%|‚ñà‚ñà‚ñà‚ñà‚ñà‚ñà‚ñà‚ñà‚ñà‚ñà| 9/9 [00:00<00:00, 11363.26it/s]
  0%|          | 0/9 [00:00<?, ?it/s]100%|‚ñà‚ñà‚ñà‚ñà‚ñà‚ñà‚ñà‚ñà‚ñà‚ñà| 9/9 [00:00<00:00, 11109.10it/s]
  0%|          | 0/9 [00:00<?, ?it/s]100%|‚ñà‚ñà‚ñà‚ñà‚ñà‚ñà‚ñà‚ñà‚ñà‚ñà| 9/9 [00:00<00:00, 11505.25it/s]
/home/otto.tavares/public/iltbi/rxp2p-cycle/p2p-cycle-env/lib/python3.9/site-packages/torch/utils/data/dataloader.py:558: UserWarning: This DataLoader will create 4 worker processes in total. Our suggested max number of worker in current system is 1, which is smaller than what this DataLoader is going to create. Please be aware that excessive worker creation might get DataLoader running slow or even freeze, lower the worker number to avoid potential slowness/freeze if necessary.
  warnings.warn(_create_warning_msg(
Setting up a new session...
Traceback (most recent call last):
  File "/home/otto.tavares/public/iltbi/rxp2p-cycle/p2p-cycle-env/lib/python3.9/site-packages/urllib3/connection.py", line 198, in _new_conn
    sock = connection.create_connection(
  File "/home/otto.tavares/public/iltbi/rxp2p-cycle/p2p-cycle-env/lib/python3.9/site-packages/urllib3/util/connection.py", line 85, in create_connection
    raise err
  File "/home/otto.tavares/public/iltbi/rxp2p-cycle/p2p-cycle-env/lib/python3.9/site-packages/urllib3/util/connection.py", line 73, in create_connection
    sock.connect(sa)
ConnectionRefusedError: [Errno 111] Connection refused

The above exception was the direct cause of the following exception:

Traceback (most recent call last):
  File "/home/otto.tavares/public/iltbi/rxp2p-cycle/p2p-cycle-env/lib/python3.9/site-packages/urllib3/connectionpool.py", line 793, in urlopen
    response = self._make_request(
  File "/home/otto.tavares/public/iltbi/rxp2p-cycle/p2p-cycle-env/lib/python3.9/site-packages/urllib3/connectionpool.py", line 496, in _make_request
    conn.request(
  File "/home/otto.tavares/public/iltbi/rxp2p-cycle/p2p-cycle-env/lib/python3.9/site-packages/urllib3/connection.py", line 400, in request
    self.endheaders()
  File "/usr/lib/python3.9/http/client.py", line 1250, in endheaders
    self._send_output(message_body, encode_chunked=encode_chunked)
  File "/usr/lib/python3.9/http/client.py", line 1010, in _send_output
    self.send(msg)
  File "/usr/lib/python3.9/http/client.py", line 950, in send
    self.connect()
  File "/home/otto.tavares/public/iltbi/rxp2p-cycle/p2p-cycle-env/lib/python3.9/site-packages/urllib3/connection.py", line 238, in connect
    self.sock = self._new_conn()
  File "/home/otto.tavares/public/iltbi/rxp2p-cycle/p2p-cycle-env/lib/python3.9/site-packages/urllib3/connection.py", line 213, in _new_conn
    raise NewConnectionError(
urllib3.exceptions.NewConnectionError: <urllib3.connection.HTTPConnection object at 0x7f730624c850>: Failed to establish a new connection: [Errno 111] Connection refused

The above exception was the direct cause of the following exception:

Traceback (most recent call last):
  File "/home/otto.tavares/public/iltbi/rxp2p-cycle/p2p-cycle-env/lib/python3.9/site-packages/requests/adapters.py", line 486, in send
    resp = conn.urlopen(
  File "/home/otto.tavares/public/iltbi/rxp2p-cycle/p2p-cycle-env/lib/python3.9/site-packages/urllib3/connectionpool.py", line 847, in urlopen
    retries = retries.increment(
  File "/home/otto.tavares/public/iltbi/rxp2p-cycle/p2p-cycle-env/lib/python3.9/site-packages/urllib3/util/retry.py", line 515, in increment
    raise MaxRetryError(_pool, url, reason) from reason  # type: ignore[arg-type]
urllib3.exceptions.MaxRetryError: HTTPConnectionPool(host='localhost', port=8097): Max retries exceeded with url: /env/main (Caused by NewConnectionError('<urllib3.connection.HTTPConnection object at 0x7f730624c850>: Failed to establish a new connection: [Errno 111] Connection refused'))

During handling of the above exception, another exception occurred:

Traceback (most recent call last):
  File "/home/otto.tavares/public/iltbi/rxp2p-cycle/p2p-cycle-env/lib/python3.9/site-packages/visdom/__init__.py", line 756, in _send
    return self._handle_post(
  File "/home/otto.tavares/public/iltbi/rxp2p-cycle/p2p-cycle-env/lib/python3.9/site-packages/visdom/__init__.py", line 720, in _handle_post
    r = self.session.post(url, data=data)
  File "/home/otto.tavares/public/iltbi/rxp2p-cycle/p2p-cycle-env/lib/python3.9/site-packages/requests/sessions.py", line 637, in post
    return self.request("POST", url, data=data, json=json, **kwargs)
  File "/home/otto.tavares/public/iltbi/rxp2p-cycle/p2p-cycle-env/lib/python3.9/site-packages/requests/sessions.py", line 589, in request
    resp = self.send(prep, **send_kwargs)
  File "/home/otto.tavares/public/iltbi/rxp2p-cycle/p2p-cycle-env/lib/python3.9/site-packages/requests/sessions.py", line 703, in send
    r = adapter.send(request, **kwargs)
  File "/home/otto.tavares/public/iltbi/rxp2p-cycle/p2p-cycle-env/lib/python3.9/site-packages/requests/adapters.py", line 519, in send
    raise ConnectionError(e, request=request)
requests.exceptions.ConnectionError: HTTPConnectionPool(host='localhost', port=8097): Max retries exceeded with url: /env/main (Caused by NewConnectionError('<urllib3.connection.HTTPConnection object at 0x7f730624c850>: Failed to establish a new connection: [Errno 111] Connection refused'))
[Errno 111] Connection refused
on_close() takes 1 positional argument but 3 were given
wandb: Currently logged in as: otavares. Use `wandb login --relogin` to force relogin
wandb: wandb version 0.17.0 is available!  To upgrade, please run:
wandb:  $ pip install wandb --upgrade
wandb: Tracking run with wandb version 0.16.6
wandb: Run data is saved locally in /home/otto.tavares/public/iltbi/rxp2p-cycle/wandb/run-20240508_091945-cycle_ntb_test_1_sort_3
wandb: Run `wandb offline` to turn off syncing.
wandb: Syncing run test_1_sort_3
wandb: ‚≠êÔ∏è View project at https://wandb.ai/otavares/cycle_shenzhen_ntb_santacasa
wandb: üöÄ View run at https://wandb.ai/otavares/cycle_shenzhen_ntb_santacasa/runs/cycle_ntb_test_1_sort_3
/home/otto.tavares/public/iltbi/rxp2p-cycle/p2p-cycle-env/lib/python3.9/site-packages/torch/optim/lr_scheduler.py:143: UserWarning: Detected call of `lr_scheduler.step()` before `optimizer.step()`. In PyTorch 1.1.0 and later, you should call them in the opposite order: `optimizer.step()` before `lr_scheduler.step()`.  Failure to do this will result in PyTorch skipping the first value of the learning rate schedule. See more details at https://pytorch.org/docs/stable/optim.html#how-to-adjust-learning-rate
  warnings.warn("Detected call of `lr_scheduler.step()` before `optimizer.step()`. "
/home/otto.tavares/public/iltbi/rxp2p-cycle/p2p-cycle-env/lib/python3.9/site-packages/torch/utils/data/dataloader.py:558: UserWarning: This DataLoader will create 4 worker processes in total. Our suggested max number of worker in current system is 1, which is smaller than what this DataLoader is going to create. Please be aware that excessive worker creation might get DataLoader running slow or even freeze, lower the worker number to avoid potential slowness/freeze if necessary.
  warnings.warn(_create_warning_msg(
wandb: - 181.092 MB of 181.092 MB uploaded (0.101 MB deduped)wandb: \ 181.092 MB of 181.092 MB uploaded (0.101 MB deduped)wandb: | 183.042 MB of 183.042 MB uploaded (0.101 MB deduped)wandb: / 183.042 MB of 183.042 MB uploaded (0.101 MB deduped)wandb: - 183.042 MB of 183.042 MB uploaded (0.101 MB deduped)wandb: \ 183.042 MB of 183.042 MB uploaded (0.101 MB deduped)wandb: 
wandb: Run history:
wandb:                D_A ‚ñÉ‚ñÉ‚ñÉ‚ñÉ‚ñá‚ñÖ‚ñÖ‚ñÉ‚ñà‚ñá‚ñÇ‚ñÇ‚ñÑ‚ñÑ‚ñÑ‚ñÉ‚ñÖ‚ñÑ‚ñÇ‚ñÖ‚ñÑ‚ñÇ‚ñÅ‚ñÉ‚ñÇ‚ñÇ‚ñÇ‚ñÇ‚ñÇ‚ñÇ‚ñÅ‚ñÇ‚ñÅ‚ñÅ‚ñÇ‚ñÉ‚ñÉ‚ñÅ‚ñÇ‚ñÇ
wandb:            D_A_val ‚ñÇ‚ñÇ‚ñÇ‚ñÉ‚ñÇ‚ñÑ‚ñÑ‚ñÑ‚ñÇ‚ñá‚ñÉ‚ñÉ‚ñÉ‚ñÅ‚ñÇ‚ñÇ‚ñÑ‚ñÅ‚ñÇ‚ñÇ‚ñÜ‚ñÇ‚ñÇ‚ñÉ‚ñÉ‚ñÅ‚ñÇ‚ñÇ‚ñÇ‚ñÇ‚ñÑ‚ñÇ‚ñÅ‚ñÇ‚ñÅ‚ñà‚ñÉ‚ñÜ‚ñÉ‚ñÜ
wandb:                D_B ‚ñÑ‚ñÖ‚ñá‚ñÖ‚ñÉ‚ñÜ‚ñÇ‚ñÜ‚ñÜ‚ñá‚ñá‚ñÑ‚ñÜ‚ñá‚ñá‚ñà‚ñÉ‚ñÇ‚ñÉ‚ñÜ‚ñÅ‚ñÇ‚ñÅ‚ñÇ‚ñÅ‚ñÇ‚ñÅ‚ñÇ‚ñÇ‚ñÅ‚ñÇ‚ñÇ‚ñÅ‚ñÉ‚ñÇ‚ñÜ‚ñÇ‚ñÇ‚ñÑ‚ñÉ
wandb:            D_B_val ‚ñÇ‚ñÇ‚ñÇ‚ñÇ‚ñÇ‚ñÇ‚ñÉ‚ñÇ‚ñÇ‚ñÉ‚ñÉ‚ñÉ‚ñÉ‚ñÉ‚ñÉ‚ñÉ‚ñÇ‚ñÇ‚ñÇ‚ñÇ‚ñÇ‚ñÅ‚ñÅ‚ñÇ‚ñÇ‚ñÇ‚ñÅ‚ñÉ‚ñÇ‚ñÇ‚ñÉ‚ñÉ‚ñÉ‚ñÉ‚ñÖ‚ñÜ‚ñÑ‚ñÖ‚ñà‚ñÜ
wandb:                G_A ‚ñÖ‚ñÜ‚ñÉ‚ñà‚ñÇ‚ñÇ‚ñÇ‚ñÇ‚ñÅ‚ñÑ‚ñÇ‚ñÉ‚ñÇ‚ñÇ‚ñÇ‚ñÑ‚ñÇ‚ñÉ‚ñÖ‚ñÖ‚ñÇ‚ñÑ‚ñÑ‚ñÖ‚ñÉ‚ñá‚ñÖ‚ñÑ‚ñÑ‚ñÉ‚ñÉ‚ñÜ‚ñÖ‚ñÑ‚ñÉ‚ñÖ‚ñÜ‚ñÖ‚ñÑ‚ñÑ
wandb:            G_A_val ‚ñÉ‚ñÉ‚ñÇ‚ñÇ‚ñÇ‚ñÅ‚ñÅ‚ñÅ‚ñÑ‚ñÜ‚ñÇ‚ñÅ‚ñÇ‚ñÉ‚ñÉ‚ñÉ‚ñÇ‚ñÑ‚ñÖ‚ñÇ‚ñÉ‚ñÉ‚ñÉ‚ñÇ‚ñÉ‚ñÑ‚ñÖ‚ñÇ‚ñÑ‚ñÑ‚ñÖ‚ñÑ‚ñÉ‚ñÑ‚ñÑ‚ñÑ‚ñÜ‚ñà‚ñá‚ñÜ
wandb:                G_B ‚ñÉ‚ñÇ‚ñÇ‚ñÅ‚ñÅ‚ñÖ‚ñÖ‚ñÖ‚ñÇ‚ñÇ‚ñÅ‚ñÉ‚ñÑ‚ñÇ‚ñÇ‚ñÉ‚ñÇ‚ñÉ‚ñà‚ñÅ‚ñÜ‚ñá‚ñÑ‚ñÖ‚ñÜ‚ñÖ‚ñÜ‚ñá‚ñá‚ñÜ‚ñÑ‚ñá‚ñÖ‚ñÑ‚ñÖ‚ñÜ‚ñÑ‚ñÖ‚ñÉ‚ñÑ
wandb:            G_B_val ‚ñÑ‚ñÑ‚ñÇ‚ñÇ‚ñÉ‚ñÇ‚ñÅ‚ñÑ‚ñÉ‚ñÇ‚ñÅ‚ñÅ‚ñÅ‚ñÇ‚ñÇ‚ñÇ‚ñÇ‚ñÉ‚ñÑ‚ñÇ‚ñÖ‚ñÖ‚ñÑ‚ñÉ‚ñÇ‚ñÑ‚ñÉ‚ñÇ‚ñÜ‚ñÖ‚ñà‚ñÖ‚ñÑ‚ñÇ‚ñÖ‚ñÖ‚ñÑ‚ñá‚ñÑ‚ñÜ
wandb:     KL_realA_fakeA ‚ñÜ‚ñÑ‚ñÇ‚ñÑ‚ñÉ‚ñÅ‚ñÅ‚ñÇ‚ñÖ‚ñÅ‚ñÅ‚ñÅ‚ñÅ‚ñÑ‚ñÅ‚ñÅ‚ñÉ‚ñá‚ñÅ‚ñÇ‚ñÑ‚ñÇ‚ñÖ‚ñÇ‚ñÅ‚ñÉ‚ñÅ‚ñÖ‚ñÇ‚ñÅ‚ñÇ‚ñÜ‚ñÉ‚ñà‚ñÑ‚ñÉ‚ñÅ‚ñÅ‚ñá‚ñÇ
wandb: KL_realA_fakeA_val ‚ñÅ‚ñÅ‚ñÅ‚ñÇ‚ñÇ‚ñÉ‚ñÅ‚ñÇ‚ñÅ‚ñÇ‚ñÅ‚ñÅ‚ñÇ‚ñÅ‚ñÅ‚ñÅ‚ñÇ‚ñÅ‚ñÇ‚ñÅ‚ñÇ‚ñÜ‚ñÅ‚ñÑ‚ñÅ‚ñÇ‚ñÇ‚ñÅ‚ñÅ‚ñÇ‚ñÇ‚ñÅ‚ñÑ‚ñÅ‚ñÇ‚ñÇ‚ñÜ‚ñÑ‚ñà‚ñÅ
wandb:     KL_realB_fakeB ‚ñÇ‚ñÇ‚ñÇ‚ñÉ‚ñà‚ñÇ‚ñÇ‚ñÇ‚ñÉ‚ñÇ‚ñÇ‚ñÅ‚ñÅ‚ñÉ‚ñÅ‚ñÅ‚ñÉ‚ñÇ‚ñÇ‚ñÅ‚ñÅ‚ñÇ‚ñÅ‚ñÇ‚ñÅ‚ñÇ‚ñÇ‚ñÅ‚ñÉ‚ñÅ‚ñÇ‚ñÇ‚ñÇ‚ñÇ‚ñÉ‚ñÅ‚ñÇ‚ñÅ‚ñÅ‚ñÇ
wandb: KL_realB_fakeB_val ‚ñÑ‚ñÅ‚ñÅ‚ñÇ‚ñÉ‚ñÇ‚ñÅ‚ñÇ‚ñÇ‚ñÅ‚ñÇ‚ñÅ‚ñÇ‚ñÅ‚ñÉ‚ñÅ‚ñÅ‚ñÑ‚ñÅ‚ñÇ‚ñÖ‚ñÉ‚ñÜ‚ñÜ‚ñÉ‚ñÅ‚ñÅ‚ñÅ‚ñÅ‚ñÉ‚ñÅ‚ñÇ‚ñÇ‚ñà‚ñÖ‚ñÅ‚ñÅ‚ñÇ‚ñÉ‚ñÇ
wandb:            cycle_A ‚ñá‚ñÑ‚ñà‚ñÖ‚ñÜ‚ñÉ‚ñÑ‚ñÖ‚ñÉ‚ñÉ‚ñÉ‚ñÉ‚ñÑ‚ñÉ‚ñÑ‚ñÉ‚ñÅ‚ñÇ‚ñÉ‚ñÉ‚ñÇ‚ñÉ‚ñÑ‚ñÉ‚ñÉ‚ñÑ‚ñÉ‚ñÅ‚ñÉ‚ñÇ‚ñÉ‚ñÉ‚ñÅ‚ñÖ‚ñÅ‚ñÉ‚ñÇ‚ñÇ‚ñÇ‚ñÇ
wandb:        cycle_A_val ‚ñÑ‚ñÑ‚ñÑ‚ñÑ‚ñÉ‚ñÑ‚ñÇ‚ñÉ‚ñÑ‚ñÉ‚ñà‚ñÇ‚ñÇ‚ñÉ‚ñÇ‚ñÇ‚ñÑ‚ñÇ‚ñÉ‚ñÇ‚ñÑ‚ñà‚ñÇ‚ñÅ‚ñÇ‚ñÇ‚ñÅ‚ñÇ‚ñÅ‚ñÅ‚ñÇ‚ñÇ‚ñÅ‚ñÅ‚ñÇ‚ñÖ‚ñÅ‚ñÅ‚ñÇ‚ñÇ
wandb:            cycle_B ‚ñÜ‚ñÉ‚ñÉ‚ñÉ‚ñÜ‚ñÉ‚ñÇ‚ñÉ‚ñÇ‚ñÇ‚ñà‚ñÑ‚ñÇ‚ñÇ‚ñÇ‚ñÇ‚ñÇ‚ñÉ‚ñÑ‚ñÇ‚ñÉ‚ñÇ‚ñÖ‚ñÇ‚ñÇ‚ñÉ‚ñÇ‚ñÇ‚ñÇ‚ñÇ‚ñÅ‚ñÇ‚ñÇ‚ñÅ‚ñÇ‚ñÇ‚ñÅ‚ñÅ‚ñÅ‚ñÅ
wandb:        cycle_B_val ‚ñÜ‚ñÑ‚ñà‚ñÇ‚ñÖ‚ñÇ‚ñÑ‚ñÇ‚ñÅ‚ñÑ‚ñÉ‚ñÇ‚ñÅ‚ñÅ‚ñÑ‚ñÅ‚ñÅ‚ñÑ‚ñÇ‚ñÉ‚ñÑ‚ñÉ‚ñÜ‚ñÖ‚ñÇ‚ñÅ‚ñÇ‚ñÅ‚ñÅ‚ñÇ‚ñÇ‚ñÅ‚ñÅ‚ñÇ‚ñÇ‚ñÇ‚ñÇ‚ñÅ‚ñÇ‚ñÇ
wandb:              idt_A ‚ñá‚ñÖ‚ñÖ‚ñÑ‚ñà‚ñÖ‚ñÇ‚ñÑ‚ñÇ‚ñÉ‚ñà‚ñÑ‚ñÇ‚ñÉ‚ñÉ‚ñÉ‚ñÇ‚ñÜ‚ñÑ‚ñÇ‚ñÉ‚ñÇ‚ñÉ‚ñÇ‚ñÇ‚ñÇ‚ñÉ‚ñÇ‚ñÉ‚ñÅ‚ñÅ‚ñÇ‚ñÅ‚ñÇ‚ñÇ‚ñÅ‚ñÅ‚ñÅ‚ñÇ‚ñÅ
wandb:          idt_A_val ‚ñÖ‚ñÉ‚ñà‚ñÇ‚ñÖ‚ñÉ‚ñÉ‚ñÇ‚ñÅ‚ñÑ‚ñÉ‚ñÉ‚ñÅ‚ñÅ‚ñÇ‚ñÇ‚ñÅ‚ñÇ‚ñÅ‚ñÇ‚ñÑ‚ñÇ‚ñÉ‚ñÑ‚ñÇ‚ñÅ‚ñÇ‚ñÅ‚ñÇ‚ñÇ‚ñÅ‚ñÅ‚ñÅ‚ñÇ‚ñÇ‚ñÇ‚ñÜ‚ñÅ‚ñÅ‚ñÇ
wandb:              idt_B ‚ñÖ‚ñÉ‚ñà‚ñÑ‚ñÖ‚ñÉ‚ñÉ‚ñÑ‚ñÇ‚ñÉ‚ñÇ‚ñÇ‚ñÖ‚ñÇ‚ñÇ‚ñÇ‚ñÅ‚ñÇ‚ñÇ‚ñÉ‚ñÉ‚ñÉ‚ñÑ‚ñÇ‚ñÇ‚ñÇ‚ñÇ‚ñÅ‚ñÇ‚ñÇ‚ñÇ‚ñÇ‚ñÅ‚ñÉ‚ñÅ‚ñÇ‚ñÇ‚ñÅ‚ñÇ‚ñÇ
wandb:          idt_B_val ‚ñÑ‚ñÑ‚ñÑ‚ñÜ‚ñÖ‚ñÜ‚ñÉ‚ñÜ‚ñÑ‚ñÉ‚ñÑ‚ñÉ‚ñÉ‚ñÑ‚ñÜ‚ñÇ‚ñà‚ñÇ‚ñÖ‚ñÇ‚ñÉ‚ñÖ‚ñÑ‚ñÅ‚ñÇ‚ñÇ‚ñÇ‚ñÇ‚ñÅ‚ñÅ‚ñÇ‚ñÉ‚ñÇ‚ñÇ‚ñÇ‚ñÉ‚ñÅ‚ñÅ‚ñÇ‚ñÇ
wandb: 
wandb: Run summary:
wandb:                D_A 0.07224
wandb:            D_A_val 0.35934
wandb:                D_B 0.08071
wandb:            D_B_val 0.77982
wandb:                G_A 0.73864
wandb:            G_A_val 2.19647
wandb:                G_B 0.56841
wandb:            G_B_val 1.24349
wandb:     KL_realA_fakeA 0.14152
wandb: KL_realA_fakeA_val 0.14188
wandb:     KL_realB_fakeB 0.15451
wandb: KL_realB_fakeB_val 0.19884
wandb:            cycle_A 0.53235
wandb:        cycle_A_val 0.50253
wandb:            cycle_B 0.31646
wandb:        cycle_B_val 0.51257
wandb:              idt_A 0.08597
wandb:          idt_A_val 0.28748
wandb:              idt_B 0.18585
wandb:          idt_B_val 0.32767
wandb: 
wandb: üöÄ View run test_1_sort_3 at: https://wandb.ai/otavares/cycle_shenzhen_ntb_santacasa/runs/cycle_ntb_test_1_sort_3
wandb: ‚≠êÔ∏è View project at: https://wandb.ai/otavares/cycle_shenzhen_ntb_santacasa
wandb: Synced 6 W&B file(s), 1170 media file(s), 1170 artifact file(s) and 1 other file(s)
wandb: Find logs at: ./wandb/run-20240508_091945-cycle_ntb_test_1_sort_3/logs
