  0%|          | 0/9 [00:00<?, ?it/s]100%|‚ñà‚ñà‚ñà‚ñà‚ñà‚ñà‚ñà‚ñà‚ñà‚ñà| 9/9 [00:00<00:00, 10336.46it/s]
  0%|          | 0/9 [00:00<?, ?it/s]100%|‚ñà‚ñà‚ñà‚ñà‚ñà‚ñà‚ñà‚ñà‚ñà‚ñà| 9/9 [00:00<00:00, 10023.56it/s]
  0%|          | 0/9 [00:00<?, ?it/s]100%|‚ñà‚ñà‚ñà‚ñà‚ñà‚ñà‚ñà‚ñà‚ñà‚ñà| 9/9 [00:00<00:00, 10973.47it/s]
  0%|          | 0/9 [00:00<?, ?it/s]100%|‚ñà‚ñà‚ñà‚ñà‚ñà‚ñà‚ñà‚ñà‚ñà‚ñà| 9/9 [00:00<00:00, 11261.56it/s]
  0%|          | 0/9 [00:00<?, ?it/s]100%|‚ñà‚ñà‚ñà‚ñà‚ñà‚ñà‚ñà‚ñà‚ñà‚ñà| 9/9 [00:00<00:00, 10995.85it/s]
  0%|          | 0/9 [00:00<?, ?it/s]100%|‚ñà‚ñà‚ñà‚ñà‚ñà‚ñà‚ñà‚ñà‚ñà‚ñà| 9/9 [00:00<00:00, 11414.80it/s]
  0%|          | 0/9 [00:00<?, ?it/s]100%|‚ñà‚ñà‚ñà‚ñà‚ñà‚ñà‚ñà‚ñà‚ñà‚ñà| 9/9 [00:00<00:00, 11112.37it/s]
  0%|          | 0/9 [00:00<?, ?it/s]100%|‚ñà‚ñà‚ñà‚ñà‚ñà‚ñà‚ñà‚ñà‚ñà‚ñà| 9/9 [00:00<00:00, 11109.10it/s]
  0%|          | 0/9 [00:00<?, ?it/s]100%|‚ñà‚ñà‚ñà‚ñà‚ñà‚ñà‚ñà‚ñà‚ñà‚ñà| 9/9 [00:00<00:00, 10825.56it/s]
  0%|          | 0/9 [00:00<?, ?it/s]100%|‚ñà‚ñà‚ñà‚ñà‚ñà‚ñà‚ñà‚ñà‚ñà‚ñà| 9/9 [00:00<00:00, 10813.16it/s]
/home/otto.tavares/public/iltbi/rxp2p-cycle/p2p-cycle-env/lib/python3.9/site-packages/torch/utils/data/dataloader.py:558: UserWarning: This DataLoader will create 4 worker processes in total. Our suggested max number of worker in current system is 1, which is smaller than what this DataLoader is going to create. Please be aware that excessive worker creation might get DataLoader running slow or even freeze, lower the worker number to avoid potential slowness/freeze if necessary.
  warnings.warn(_create_warning_msg(
  0%|          | 0/9 [00:00<?, ?it/s]100%|‚ñà‚ñà‚ñà‚ñà‚ñà‚ñà‚ñà‚ñà‚ñà‚ñà| 9/9 [00:00<00:00, 10844.22it/s]
  0%|          | 0/9 [00:00<?, ?it/s]100%|‚ñà‚ñà‚ñà‚ñà‚ñà‚ñà‚ñà‚ñà‚ñà‚ñà| 9/9 [00:00<00:00, 10897.44it/s]
  0%|          | 0/9 [00:00<?, ?it/s]100%|‚ñà‚ñà‚ñà‚ñà‚ñà‚ñà‚ñà‚ñà‚ñà‚ñà| 9/9 [00:00<00:00, 11214.72it/s]
  0%|          | 0/9 [00:00<?, ?it/s]100%|‚ñà‚ñà‚ñà‚ñà‚ñà‚ñà‚ñà‚ñà‚ñà‚ñà| 9/9 [00:00<00:00, 10872.33it/s]
  0%|          | 0/9 [00:00<?, ?it/s]100%|‚ñà‚ñà‚ñà‚ñà‚ñà‚ñà‚ñà‚ñà‚ñà‚ñà| 9/9 [00:00<00:00, 10541.40it/s]
  0%|          | 0/9 [00:00<?, ?it/s]100%|‚ñà‚ñà‚ñà‚ñà‚ñà‚ñà‚ñà‚ñà‚ñà‚ñà| 9/9 [00:00<00:00, 10979.85it/s]
  0%|          | 0/9 [00:00<?, ?it/s]100%|‚ñà‚ñà‚ñà‚ñà‚ñà‚ñà‚ñà‚ñà‚ñà‚ñà| 9/9 [00:00<00:00, 10636.44it/s]
  0%|          | 0/9 [00:00<?, ?it/s]100%|‚ñà‚ñà‚ñà‚ñà‚ñà‚ñà‚ñà‚ñà‚ñà‚ñà| 9/9 [00:00<00:00, 11194.76it/s]
  0%|          | 0/9 [00:00<?, ?it/s]100%|‚ñà‚ñà‚ñà‚ñà‚ñà‚ñà‚ñà‚ñà‚ñà‚ñà| 9/9 [00:00<00:00, 11044.10it/s]
  0%|          | 0/9 [00:00<?, ?it/s]100%|‚ñà‚ñà‚ñà‚ñà‚ñà‚ñà‚ñà‚ñà‚ñà‚ñà| 9/9 [00:00<00:00, 11298.63it/s]
/home/otto.tavares/public/iltbi/rxp2p-cycle/p2p-cycle-env/lib/python3.9/site-packages/torch/utils/data/dataloader.py:558: UserWarning: This DataLoader will create 4 worker processes in total. Our suggested max number of worker in current system is 1, which is smaller than what this DataLoader is going to create. Please be aware that excessive worker creation might get DataLoader running slow or even freeze, lower the worker number to avoid potential slowness/freeze if necessary.
  warnings.warn(_create_warning_msg(
Setting up a new session...
Traceback (most recent call last):
  File "/home/otto.tavares/public/iltbi/rxp2p-cycle/p2p-cycle-env/lib/python3.9/site-packages/urllib3/connection.py", line 198, in _new_conn
    sock = connection.create_connection(
  File "/home/otto.tavares/public/iltbi/rxp2p-cycle/p2p-cycle-env/lib/python3.9/site-packages/urllib3/util/connection.py", line 85, in create_connection
    raise err
  File "/home/otto.tavares/public/iltbi/rxp2p-cycle/p2p-cycle-env/lib/python3.9/site-packages/urllib3/util/connection.py", line 73, in create_connection
    sock.connect(sa)
ConnectionRefusedError: [Errno 111] Connection refused

The above exception was the direct cause of the following exception:

Traceback (most recent call last):
  File "/home/otto.tavares/public/iltbi/rxp2p-cycle/p2p-cycle-env/lib/python3.9/site-packages/urllib3/connectionpool.py", line 793, in urlopen
    response = self._make_request(
  File "/home/otto.tavares/public/iltbi/rxp2p-cycle/p2p-cycle-env/lib/python3.9/site-packages/urllib3/connectionpool.py", line 496, in _make_request
    conn.request(
  File "/home/otto.tavares/public/iltbi/rxp2p-cycle/p2p-cycle-env/lib/python3.9/site-packages/urllib3/connection.py", line 400, in request
    self.endheaders()
  File "/usr/lib/python3.9/http/client.py", line 1250, in endheaders
    self._send_output(message_body, encode_chunked=encode_chunked)
  File "/usr/lib/python3.9/http/client.py", line 1010, in _send_output
    self.send(msg)
  File "/usr/lib/python3.9/http/client.py", line 950, in send
    self.connect()
  File "/home/otto.tavares/public/iltbi/rxp2p-cycle/p2p-cycle-env/lib/python3.9/site-packages/urllib3/connection.py", line 238, in connect
    self.sock = self._new_conn()
  File "/home/otto.tavares/public/iltbi/rxp2p-cycle/p2p-cycle-env/lib/python3.9/site-packages/urllib3/connection.py", line 213, in _new_conn
    raise NewConnectionError(
urllib3.exceptions.NewConnectionError: <urllib3.connection.HTTPConnection object at 0x7ff6a490c490>: Failed to establish a new connection: [Errno 111] Connection refused

The above exception was the direct cause of the following exception:

Traceback (most recent call last):
  File "/home/otto.tavares/public/iltbi/rxp2p-cycle/p2p-cycle-env/lib/python3.9/site-packages/requests/adapters.py", line 486, in send
    resp = conn.urlopen(
  File "/home/otto.tavares/public/iltbi/rxp2p-cycle/p2p-cycle-env/lib/python3.9/site-packages/urllib3/connectionpool.py", line 847, in urlopen
    retries = retries.increment(
  File "/home/otto.tavares/public/iltbi/rxp2p-cycle/p2p-cycle-env/lib/python3.9/site-packages/urllib3/util/retry.py", line 515, in increment
    raise MaxRetryError(_pool, url, reason) from reason  # type: ignore[arg-type]
urllib3.exceptions.MaxRetryError: HTTPConnectionPool(host='localhost', port=8097): Max retries exceeded with url: /env/main (Caused by NewConnectionError('<urllib3.connection.HTTPConnection object at 0x7ff6a490c490>: Failed to establish a new connection: [Errno 111] Connection refused'))

During handling of the above exception, another exception occurred:

Traceback (most recent call last):
  File "/home/otto.tavares/public/iltbi/rxp2p-cycle/p2p-cycle-env/lib/python3.9/site-packages/visdom/__init__.py", line 756, in _send
    return self._handle_post(
  File "/home/otto.tavares/public/iltbi/rxp2p-cycle/p2p-cycle-env/lib/python3.9/site-packages/visdom/__init__.py", line 720, in _handle_post
    r = self.session.post(url, data=data)
  File "/home/otto.tavares/public/iltbi/rxp2p-cycle/p2p-cycle-env/lib/python3.9/site-packages/requests/sessions.py", line 637, in post
    return self.request("POST", url, data=data, json=json, **kwargs)
  File "/home/otto.tavares/public/iltbi/rxp2p-cycle/p2p-cycle-env/lib/python3.9/site-packages/requests/sessions.py", line 589, in request
    resp = self.send(prep, **send_kwargs)
  File "/home/otto.tavares/public/iltbi/rxp2p-cycle/p2p-cycle-env/lib/python3.9/site-packages/requests/sessions.py", line 703, in send
    r = adapter.send(request, **kwargs)
  File "/home/otto.tavares/public/iltbi/rxp2p-cycle/p2p-cycle-env/lib/python3.9/site-packages/requests/adapters.py", line 519, in send
    raise ConnectionError(e, request=request)
requests.exceptions.ConnectionError: HTTPConnectionPool(host='localhost', port=8097): Max retries exceeded with url: /env/main (Caused by NewConnectionError('<urllib3.connection.HTTPConnection object at 0x7ff6a490c490>: Failed to establish a new connection: [Errno 111] Connection refused'))
[Errno 111] Connection refused
on_close() takes 1 positional argument but 3 were given
wandb: Currently logged in as: otavares. Use `wandb login --relogin` to force relogin
wandb: Tracking run with wandb version 0.16.6
wandb: Run data is saved locally in /home/otto.tavares/public/iltbi/rxp2p-cycle/wandb/run-20240507_004318-cycle_ntb_test_0_sort_4
wandb: Run `wandb offline` to turn off syncing.
wandb: Syncing run test_0_sort_4
wandb: ‚≠êÔ∏è View project at https://wandb.ai/otavares/cycle_shenzhen_ntb_santacasa
wandb: üöÄ View run at https://wandb.ai/otavares/cycle_shenzhen_ntb_santacasa/runs/cycle_ntb_test_0_sort_4
/home/otto.tavares/public/iltbi/rxp2p-cycle/p2p-cycle-env/lib/python3.9/site-packages/torch/optim/lr_scheduler.py:143: UserWarning: Detected call of `lr_scheduler.step()` before `optimizer.step()`. In PyTorch 1.1.0 and later, you should call them in the opposite order: `optimizer.step()` before `lr_scheduler.step()`.  Failure to do this will result in PyTorch skipping the first value of the learning rate schedule. See more details at https://pytorch.org/docs/stable/optim.html#how-to-adjust-learning-rate
  warnings.warn("Detected call of `lr_scheduler.step()` before `optimizer.step()`. "
/home/otto.tavares/public/iltbi/rxp2p-cycle/p2p-cycle-env/lib/python3.9/site-packages/torch/utils/data/dataloader.py:558: UserWarning: This DataLoader will create 4 worker processes in total. Our suggested max number of worker in current system is 1, which is smaller than what this DataLoader is going to create. Please be aware that excessive worker creation might get DataLoader running slow or even freeze, lower the worker number to avoid potential slowness/freeze if necessary.
  warnings.warn(_create_warning_msg(
wandb: ERROR Error uploading "/home/otto.tavares/.local/share/wandb/artifacts/staging/tmpun1foxye": PermissionError, [Errno 13] Permission denied: '/home/otto.tavares/.cache/wandb/artifacts/obj/md5/e7/bf7303579a7074cd225c7a8635824a'
wandb: ERROR Uploading artifact file failed. Artifact won't be committed.
wandb: - 182.191 MB of 182.237 MB uploadedwandb: \ 184.142 MB of 184.188 MB uploadedwandb: | 184.142 MB of 184.188 MB uploadedwandb: / 184.142 MB of 184.188 MB uploadedwandb: 
wandb: Run history:
wandb:                D_A ‚ñÖ‚ñá‚ñÇ‚ñÑ‚ñÇ‚ñÑ‚ñÉ‚ñÇ‚ñÜ‚ñÜ‚ñÉ‚ñà‚ñÉ‚ñÖ‚ñá‚ñÉ‚ñÇ‚ñÜ‚ñÇ‚ñÅ‚ñÜ‚ñÉ‚ñÅ‚ñÇ‚ñÑ‚ñÑ‚ñÅ‚ñÅ‚ñÇ‚ñÉ‚ñÉ‚ñÅ‚ñÇ‚ñÇ‚ñÅ‚ñÉ‚ñÇ‚ñÅ‚ñÇ‚ñÅ
wandb:            D_A_val ‚ñÉ‚ñÇ‚ñÅ‚ñÇ‚ñÇ‚ñÇ‚ñÇ‚ñÅ‚ñÉ‚ñÉ‚ñÇ‚ñÇ‚ñÇ‚ñÇ‚ñÇ‚ñÉ‚ñÉ‚ñÇ‚ñÇ‚ñÅ‚ñÉ‚ñÅ‚ñÅ‚ñÅ‚ñÇ‚ñÇ‚ñÅ‚ñÇ‚ñÇ‚ñÇ‚ñÅ‚ñÅ‚ñÇ‚ñÇ‚ñÉ‚ñÅ‚ñá‚ñÑ‚ñÉ‚ñà
wandb:                D_B ‚ñÉ‚ñÑ‚ñÉ‚ñÉ‚ñÉ‚ñÑ‚ñÖ‚ñÜ‚ñÜ‚ñÇ‚ñÇ‚ñÜ‚ñÉ‚ñà‚ñá‚ñÑ‚ñÖ‚ñÉ‚ñÉ‚ñÑ‚ñÑ‚ñÉ‚ñÖ‚ñÖ‚ñÇ‚ñÉ‚ñÇ‚ñÇ‚ñÇ‚ñÇ‚ñÑ‚ñÇ‚ñÉ‚ñÅ‚ñÉ‚ñÇ‚ñÇ‚ñÅ‚ñÇ‚ñÉ
wandb:            D_B_val ‚ñÅ‚ñÅ‚ñÅ‚ñÅ‚ñÅ‚ñÅ‚ñÅ‚ñÅ‚ñÅ‚ñÅ‚ñÅ‚ñÅ‚ñÅ‚ñÅ‚ñÅ‚ñÅ‚ñÅ‚ñÅ‚ñà‚ñÅ‚ñÅ‚ñÅ‚ñÅ‚ñÅ‚ñÅ‚ñÅ‚ñÇ‚ñÅ‚ñÅ‚ñÇ‚ñÅ‚ñÅ‚ñÇ‚ñÅ‚ñÇ‚ñÅ‚ñÇ‚ñÅ‚ñÇ‚ñÅ
wandb:                G_A ‚ñÉ‚ñÇ‚ñÉ‚ñÇ‚ñá‚ñÉ‚ñÉ‚ñÜ‚ñÇ‚ñÇ‚ñÉ‚ñÉ‚ñÇ‚ñÇ‚ñÅ‚ñÇ‚ñà‚ñÅ‚ñÉ‚ñÇ‚ñÇ‚ñÉ‚ñÖ‚ñÉ‚ñÑ‚ñÇ‚ñÑ‚ñÉ‚ñÉ‚ñÉ‚ñÉ‚ñÑ‚ñÉ‚ñÖ‚ñÖ‚ñÇ‚ñÑ‚ñÑ‚ñÑ‚ñÑ
wandb:            G_A_val ‚ñÅ‚ñÇ‚ñÇ‚ñÅ‚ñÉ‚ñÇ‚ñÅ‚ñÇ‚ñÅ‚ñÅ‚ñÅ‚ñÇ‚ñÅ‚ñÅ‚ñÅ‚ñÇ‚ñÅ‚ñÅ‚ñÉ‚ñÇ‚ñÅ‚ñÇ‚ñÇ‚ñÇ‚ñÉ‚ñÇ‚ñÉ‚ñÇ‚ñÇ‚ñÑ‚ñÉ‚ñÇ‚ñÇ‚ñÇ‚ñÉ‚ñÉ‚ñà‚ñÑ‚ñÇ‚ñÉ
wandb:                G_B ‚ñÉ‚ñÑ‚ñÖ‚ñÑ‚ñÖ‚ñÉ‚ñÇ‚ñÇ‚ñÉ‚ñÉ‚ñÑ‚ñÇ‚ñÖ‚ñÇ‚ñÅ‚ñÇ‚ñÇ‚ñÉ‚ñÇ‚ñÇ‚ñÇ‚ñÉ‚ñÇ‚ñÉ‚ñÉ‚ñÇ‚ñÉ‚ñÑ‚ñÇ‚ñá‚ñà‚ñÑ‚ñÉ‚ñÑ‚ñÖ‚ñÉ‚ñÑ‚ñÉ‚ñÑ‚ñÑ
wandb:            G_B_val ‚ñÅ‚ñÅ‚ñÇ‚ñÇ‚ñÇ‚ñÇ‚ñÅ‚ñÅ‚ñÅ‚ñÇ‚ñÇ‚ñÅ‚ñÅ‚ñÅ‚ñÅ‚ñÅ‚ñÅ‚ñÇ‚ñà‚ñÅ‚ñÇ‚ñÅ‚ñÅ‚ñÅ‚ñÇ‚ñÇ‚ñÉ‚ñÇ‚ñÇ‚ñÇ‚ñÇ‚ñÅ‚ñÉ‚ñÇ‚ñÇ‚ñÇ‚ñÉ‚ñÇ‚ñÉ‚ñÇ
wandb:     KL_realA_fakeA ‚ñÉ‚ñÇ‚ñÇ‚ñÅ‚ñÅ‚ñÅ‚ñÉ‚ñÇ‚ñÅ‚ñÇ‚ñÇ‚ñÅ‚ñÑ‚ñÅ‚ñà‚ñÅ‚ñÅ‚ñÅ‚ñÇ‚ñÅ‚ñÅ‚ñÅ‚ñÅ‚ñÅ‚ñÅ‚ñÑ‚ñÅ‚ñÅ‚ñÅ‚ñÇ‚ñÅ‚ñÉ‚ñÉ‚ñÅ‚ñÉ‚ñÅ‚ñÅ‚ñÑ‚ñÅ‚ñÅ
wandb: KL_realA_fakeA_val ‚ñÅ‚ñÜ‚ñÇ‚ñÑ‚ñÜ‚ñÇ‚ñÇ‚ñÇ‚ñÉ‚ñÅ‚ñÅ‚ñÉ‚ñÅ‚ñÅ‚ñÜ‚ñÑ‚ñÇ‚ñÑ‚ñÉ‚ñÇ‚ñÅ‚ñÜ‚ñÉ‚ñÅ‚ñÑ‚ñà‚ñÇ‚ñÜ‚ñÅ‚ñÑ‚ñÖ‚ñÑ‚ñÉ‚ñÇ‚ñÇ‚ñá‚ñÖ‚ñÇ‚ñÅ‚ñÇ
wandb:     KL_realB_fakeB ‚ñà‚ñÅ‚ñÅ‚ñÇ‚ñÇ‚ñá‚ñÅ‚ñÇ‚ñÅ‚ñÇ‚ñÇ‚ñÉ‚ñÉ‚ñÅ‚ñÇ‚ñÇ‚ñÇ‚ñÅ‚ñÅ‚ñÅ‚ñÇ‚ñÇ‚ñÇ‚ñÅ‚ñÜ‚ñÇ‚ñÇ‚ñÅ‚ñÅ‚ñÅ‚ñÜ‚ñÇ‚ñÅ‚ñÇ‚ñÇ‚ñÅ‚ñÇ‚ñÅ‚ñÉ‚ñÜ
wandb: KL_realB_fakeB_val ‚ñÉ‚ñÜ‚ñÇ‚ñÅ‚ñÑ‚ñÇ‚ñÇ‚ñÅ‚ñÇ‚ñà‚ñÅ‚ñÇ‚ñÅ‚ñÅ‚ñÅ‚ñÇ‚ñÉ‚ñÖ‚ñÇ‚ñÇ‚ñÅ‚ñÇ‚ñÇ‚ñÇ‚ñÇ‚ñÅ‚ñÉ‚ñÉ‚ñÇ‚ñÇ‚ñÇ‚ñÅ‚ñÉ‚ñÇ‚ñÅ‚ñÇ‚ñÑ‚ñÅ‚ñÇ‚ñÅ
wandb:            cycle_A ‚ñá‚ñÜ‚ñà‚ñÜ‚ñà‚ñÖ‚ñá‚ñÖ‚ñÑ‚ñÇ‚ñÜ‚ñÑ‚ñÉ‚ñÉ‚ñÑ‚ñÑ‚ñÉ‚ñÉ‚ñÑ‚ñÉ‚ñÉ‚ñÉ‚ñÉ‚ñÑ‚ñÉ‚ñÇ‚ñÉ‚ñÉ‚ñÉ‚ñÉ‚ñÉ‚ñÇ‚ñÇ‚ñÉ‚ñÅ‚ñÉ‚ñÉ‚ñÅ‚ñÉ‚ñÇ
wandb:        cycle_A_val ‚ñÜ‚ñÉ‚ñÑ‚ñÇ‚ñà‚ñÖ‚ñÜ‚ñÑ‚ñÇ‚ñÇ‚ñÇ‚ñÑ‚ñÑ‚ñÑ‚ñÉ‚ñÖ‚ñÉ‚ñà‚ñÉ‚ñÉ‚ñÇ‚ñÑ‚ñÉ‚ñÇ‚ñÇ‚ñÅ‚ñÖ‚ñÅ‚ñÉ‚ñÖ‚ñÉ‚ñÅ‚ñÉ‚ñÇ‚ñÇ‚ñÇ‚ñÖ‚ñÅ‚ñÉ‚ñÇ
wandb:            cycle_B ‚ñà‚ñÖ‚ñÜ‚ñÖ‚ñá‚ñá‚ñÇ‚ñÉ‚ñÉ‚ñÇ‚ñÉ‚ñÉ‚ñÉ‚ñÇ‚ñÇ‚ñÉ‚ñÇ‚ñÉ‚ñÇ‚ñÇ‚ñÖ‚ñÇ‚ñÅ‚ñÇ‚ñÉ‚ñÇ‚ñÇ‚ñÇ‚ñÅ‚ñÇ‚ñÑ‚ñÇ‚ñÅ‚ñÉ‚ñÇ‚ñÅ‚ñÅ‚ñÇ‚ñÇ‚ñÇ
wandb:        cycle_B_val ‚ñà‚ñÉ‚ñÉ‚ñÉ‚ñÑ‚ñÇ‚ñÇ‚ñÇ‚ñÖ‚ñÇ‚ñÇ‚ñÇ‚ñÇ‚ñÇ‚ñÇ‚ñÇ‚ñÇ‚ñÇ‚ñÉ‚ñÇ‚ñÇ‚ñÇ‚ñÅ‚ñÅ‚ñÉ‚ñÅ‚ñÅ‚ñÅ‚ñÅ‚ñÅ‚ñÅ‚ñÅ‚ñÑ‚ñÅ‚ñá‚ñÇ‚ñÉ‚ñÇ‚ñÉ‚ñÇ
wandb:              idt_A ‚ñÖ‚ñÖ‚ñÖ‚ñÖ‚ñÖ‚ñà‚ñÇ‚ñÉ‚ñÖ‚ñÇ‚ñÇ‚ñÑ‚ñÉ‚ñÉ‚ñÇ‚ñÇ‚ñÇ‚ñÇ‚ñÇ‚ñÇ‚ñÖ‚ñÇ‚ñÇ‚ñÇ‚ñÇ‚ñÅ‚ñÉ‚ñÅ‚ñÅ‚ñÅ‚ñÉ‚ñÇ‚ñÅ‚ñÉ‚ñÉ‚ñÅ‚ñÅ‚ñÅ‚ñÇ‚ñÅ
wandb:          idt_A_val ‚ñà‚ñÑ‚ñÑ‚ñÑ‚ñÉ‚ñÉ‚ñÉ‚ñÉ‚ñÜ‚ñÉ‚ñÇ‚ñÇ‚ñÉ‚ñÇ‚ñÇ‚ñÅ‚ñÇ‚ñÅ‚ñÇ‚ñÇ‚ñÇ‚ñÇ‚ñÇ‚ñÇ‚ñÉ‚ñÅ‚ñÅ‚ñÅ‚ñÇ‚ñÅ‚ñÅ‚ñÇ‚ñÑ‚ñÅ‚ñÇ‚ñÇ‚ñÉ‚ñÅ‚ñÉ‚ñÅ
wandb:              idt_B ‚ñÜ‚ñÑ‚ñá‚ñà‚ñÉ‚ñÉ‚ñÉ‚ñÑ‚ñÑ‚ñÇ‚ñÑ‚ñÉ‚ñÇ‚ñÇ‚ñÉ‚ñÉ‚ñÉ‚ñÉ‚ñÉ‚ñÉ‚ñÉ‚ñÇ‚ñÇ‚ñÇ‚ñÇ‚ñÇ‚ñÇ‚ñÇ‚ñÇ‚ñÇ‚ñÇ‚ñÇ‚ñÅ‚ñÇ‚ñÅ‚ñÇ‚ñÇ‚ñÅ‚ñÇ‚ñÇ
wandb:          idt_B_val ‚ñÑ‚ñÑ‚ñÉ‚ñÇ‚ñá‚ñÑ‚ñÉ‚ñÉ‚ñÇ‚ñÇ‚ñÇ‚ñÇ‚ñÑ‚ñÇ‚ñÉ‚ñÑ‚ñÇ‚ñà‚ñÇ‚ñÇ‚ñÉ‚ñÉ‚ñÇ‚ñÇ‚ñÅ‚ñÅ‚ñÜ‚ñÅ‚ñÇ‚ñÖ‚ñÇ‚ñÅ‚ñÇ‚ñÇ‚ñÇ‚ñÅ‚ñÖ‚ñÅ‚ñÉ‚ñÅ
wandb: 
wandb: Run summary:
wandb:                D_A 0.01541
wandb:            D_A_val 0.36024
wandb:                D_B 0.13576
wandb:            D_B_val 1.13913
wandb:                G_A 0.78344
wandb:            G_A_val 0.89754
wandb:                G_B 0.66967
wandb:            G_B_val 1.50968
wandb:     KL_realA_fakeA 0.06958
wandb: KL_realA_fakeA_val 0.06703
wandb:     KL_realB_fakeB 0.52042
wandb: KL_realB_fakeB_val 0.08456
wandb:            cycle_A 0.43716
wandb:        cycle_A_val 0.4999
wandb:            cycle_B 0.43463
wandb:        cycle_B_val 0.44751
wandb:              idt_A 0.11704
wandb:          idt_A_val 0.11147
wandb:              idt_B 0.14872
wandb:          idt_B_val 0.15958
wandb: 
wandb: üöÄ View run test_0_sort_4 at: https://wandb.ai/otavares/cycle_shenzhen_ntb_santacasa/runs/cycle_ntb_test_0_sort_4
wandb: ‚≠êÔ∏è View project at: https://wandb.ai/otavares/cycle_shenzhen_ntb_santacasa
wandb: Synced 6 W&B file(s), 1170 media file(s), 1170 artifact file(s) and 1 other file(s)
wandb: Find logs at: ./wandb/run-20240507_004318-cycle_ntb_test_0_sort_4/logs
