  0%|          | 0/9 [00:00<?, ?it/s]100%|‚ñà‚ñà‚ñà‚ñà‚ñà‚ñà‚ñà‚ñà‚ñà‚ñà| 9/9 [00:00<00:00, 2201.99it/s]
  0%|          | 0/9 [00:00<?, ?it/s]100%|‚ñà‚ñà‚ñà‚ñà‚ñà‚ñà‚ñà‚ñà‚ñà‚ñà| 9/9 [00:00<00:00, 9729.06it/s]
  0%|          | 0/9 [00:00<?, ?it/s]100%|‚ñà‚ñà‚ñà‚ñà‚ñà‚ñà‚ñà‚ñà‚ñà‚ñà| 9/9 [00:00<00:00, 10302.60it/s]
  0%|          | 0/9 [00:00<?, ?it/s]100%|‚ñà‚ñà‚ñà‚ñà‚ñà‚ñà‚ñà‚ñà‚ñà‚ñà| 9/9 [00:00<00:00, 10660.47it/s]
  0%|          | 0/9 [00:00<?, ?it/s]100%|‚ñà‚ñà‚ñà‚ñà‚ñà‚ñà‚ñà‚ñà‚ñà‚ñà| 9/9 [00:00<00:00, 10919.51it/s]
  0%|          | 0/9 [00:00<?, ?it/s]100%|‚ñà‚ñà‚ñà‚ñà‚ñà‚ñà‚ñà‚ñà‚ñà‚ñà| 9/9 [00:00<00:00, 10503.27it/s]
  0%|          | 0/9 [00:00<?, ?it/s]100%|‚ñà‚ñà‚ñà‚ñà‚ñà‚ñà‚ñà‚ñà‚ñà‚ñà| 9/9 [00:00<00:00, 10785.35it/s]
  0%|          | 0/9 [00:00<?, ?it/s]100%|‚ñà‚ñà‚ñà‚ñà‚ñà‚ñà‚ñà‚ñà‚ñà‚ñà| 9/9 [00:00<00:00, 10427.83it/s]
  0%|          | 0/9 [00:00<?, ?it/s]100%|‚ñà‚ñà‚ñà‚ñà‚ñà‚ñà‚ñà‚ñà‚ñà‚ñà| 9/9 [00:00<00:00, 10479.94it/s]
  0%|          | 0/9 [00:00<?, ?it/s]100%|‚ñà‚ñà‚ñà‚ñà‚ñà‚ñà‚ñà‚ñà‚ñà‚ñà| 9/9 [00:00<00:00, 10387.65it/s]
/home/otto.tavares/public/iltbi/rxp2p-cycle/p2p-cycle-env/lib/python3.9/site-packages/torch/utils/data/dataloader.py:558: UserWarning: This DataLoader will create 4 worker processes in total. Our suggested max number of worker in current system is 1, which is smaller than what this DataLoader is going to create. Please be aware that excessive worker creation might get DataLoader running slow or even freeze, lower the worker number to avoid potential slowness/freeze if necessary.
  warnings.warn(_create_warning_msg(
  0%|          | 0/9 [00:00<?, ?it/s]100%|‚ñà‚ñà‚ñà‚ñà‚ñà‚ñà‚ñà‚ñà‚ñà‚ñà| 9/9 [00:00<00:00, 10479.94it/s]
  0%|          | 0/9 [00:00<?, ?it/s]100%|‚ñà‚ñà‚ñà‚ñà‚ñà‚ñà‚ñà‚ñà‚ñà‚ñà| 9/9 [00:00<00:00, 10579.80it/s]
  0%|          | 0/9 [00:00<?, ?it/s]100%|‚ñà‚ñà‚ñà‚ñà‚ñà‚ñà‚ñà‚ñà‚ñà‚ñà| 9/9 [00:00<00:00, 10031.55it/s]
  0%|          | 0/9 [00:00<?, ?it/s]100%|‚ñà‚ñà‚ñà‚ñà‚ñà‚ñà‚ñà‚ñà‚ñà‚ñà| 9/9 [00:00<00:00, 10866.07it/s]
  0%|          | 0/9 [00:00<?, ?it/s]100%|‚ñà‚ñà‚ñà‚ñà‚ñà‚ñà‚ñà‚ñà‚ñà‚ñà| 9/9 [00:00<00:00, 10810.06it/s]
  0%|          | 0/9 [00:00<?, ?it/s]100%|‚ñà‚ñà‚ñà‚ñà‚ñà‚ñà‚ñà‚ñà‚ñà‚ñà| 9/9 [00:00<00:00, 10806.97it/s]
  0%|          | 0/9 [00:00<?, ?it/s]100%|‚ñà‚ñà‚ñà‚ñà‚ñà‚ñà‚ñà‚ñà‚ñà‚ñà| 9/9 [00:00<00:00, 10559.09it/s]
  0%|          | 0/9 [00:00<?, ?it/s]100%|‚ñà‚ñà‚ñà‚ñà‚ñà‚ñà‚ñà‚ñà‚ñà‚ñà| 9/9 [00:00<00:00, 9782.00it/s]
  0%|          | 0/9 [00:00<?, ?it/s]100%|‚ñà‚ñà‚ñà‚ñà‚ñà‚ñà‚ñà‚ñà‚ñà‚ñà| 9/9 [00:00<00:00, 10733.22it/s]
  0%|          | 0/9 [00:00<?, ?it/s]100%|‚ñà‚ñà‚ñà‚ñà‚ñà‚ñà‚ñà‚ñà‚ñà‚ñà| 9/9 [00:00<00:00, 10185.84it/s]
/home/otto.tavares/public/iltbi/rxp2p-cycle/p2p-cycle-env/lib/python3.9/site-packages/torch/utils/data/dataloader.py:558: UserWarning: This DataLoader will create 4 worker processes in total. Our suggested max number of worker in current system is 1, which is smaller than what this DataLoader is going to create. Please be aware that excessive worker creation might get DataLoader running slow or even freeze, lower the worker number to avoid potential slowness/freeze if necessary.
  warnings.warn(_create_warning_msg(
Setting up a new session...
Traceback (most recent call last):
  File "/home/otto.tavares/public/iltbi/rxp2p-cycle/p2p-cycle-env/lib/python3.9/site-packages/urllib3/connection.py", line 198, in _new_conn
    sock = connection.create_connection(
  File "/home/otto.tavares/public/iltbi/rxp2p-cycle/p2p-cycle-env/lib/python3.9/site-packages/urllib3/util/connection.py", line 85, in create_connection
    raise err
  File "/home/otto.tavares/public/iltbi/rxp2p-cycle/p2p-cycle-env/lib/python3.9/site-packages/urllib3/util/connection.py", line 73, in create_connection
    sock.connect(sa)
ConnectionRefusedError: [Errno 111] Connection refused

The above exception was the direct cause of the following exception:

Traceback (most recent call last):
  File "/home/otto.tavares/public/iltbi/rxp2p-cycle/p2p-cycle-env/lib/python3.9/site-packages/urllib3/connectionpool.py", line 793, in urlopen
    response = self._make_request(
  File "/home/otto.tavares/public/iltbi/rxp2p-cycle/p2p-cycle-env/lib/python3.9/site-packages/urllib3/connectionpool.py", line 496, in _make_request
    conn.request(
  File "/home/otto.tavares/public/iltbi/rxp2p-cycle/p2p-cycle-env/lib/python3.9/site-packages/urllib3/connection.py", line 400, in request
    self.endheaders()
  File "/usr/lib/python3.9/http/client.py", line 1250, in endheaders
    self._send_output(message_body, encode_chunked=encode_chunked)
  File "/usr/lib/python3.9/http/client.py", line 1010, in _send_output
    self.send(msg)
  File "/usr/lib/python3.9/http/client.py", line 950, in send
    self.connect()
  File "/home/otto.tavares/public/iltbi/rxp2p-cycle/p2p-cycle-env/lib/python3.9/site-packages/urllib3/connection.py", line 238, in connect
    self.sock = self._new_conn()
  File "/home/otto.tavares/public/iltbi/rxp2p-cycle/p2p-cycle-env/lib/python3.9/site-packages/urllib3/connection.py", line 213, in _new_conn
    raise NewConnectionError(
urllib3.exceptions.NewConnectionError: <urllib3.connection.HTTPConnection object at 0x7f3324e398e0>: Failed to establish a new connection: [Errno 111] Connection refused

The above exception was the direct cause of the following exception:

Traceback (most recent call last):
  File "/home/otto.tavares/public/iltbi/rxp2p-cycle/p2p-cycle-env/lib/python3.9/site-packages/requests/adapters.py", line 486, in send
    resp = conn.urlopen(
  File "/home/otto.tavares/public/iltbi/rxp2p-cycle/p2p-cycle-env/lib/python3.9/site-packages/urllib3/connectionpool.py", line 847, in urlopen
    retries = retries.increment(
  File "/home/otto.tavares/public/iltbi/rxp2p-cycle/p2p-cycle-env/lib/python3.9/site-packages/urllib3/util/retry.py", line 515, in increment
    raise MaxRetryError(_pool, url, reason) from reason  # type: ignore[arg-type]
urllib3.exceptions.MaxRetryError: HTTPConnectionPool(host='localhost', port=8097): Max retries exceeded with url: /env/main (Caused by NewConnectionError('<urllib3.connection.HTTPConnection object at 0x7f3324e398e0>: Failed to establish a new connection: [Errno 111] Connection refused'))

During handling of the above exception, another exception occurred:

Traceback (most recent call last):
  File "/home/otto.tavares/public/iltbi/rxp2p-cycle/p2p-cycle-env/lib/python3.9/site-packages/visdom/__init__.py", line 756, in _send
    return self._handle_post(
  File "/home/otto.tavares/public/iltbi/rxp2p-cycle/p2p-cycle-env/lib/python3.9/site-packages/visdom/__init__.py", line 720, in _handle_post
    r = self.session.post(url, data=data)
  File "/home/otto.tavares/public/iltbi/rxp2p-cycle/p2p-cycle-env/lib/python3.9/site-packages/requests/sessions.py", line 637, in post
    return self.request("POST", url, data=data, json=json, **kwargs)
  File "/home/otto.tavares/public/iltbi/rxp2p-cycle/p2p-cycle-env/lib/python3.9/site-packages/requests/sessions.py", line 589, in request
    resp = self.send(prep, **send_kwargs)
  File "/home/otto.tavares/public/iltbi/rxp2p-cycle/p2p-cycle-env/lib/python3.9/site-packages/requests/sessions.py", line 703, in send
    r = adapter.send(request, **kwargs)
  File "/home/otto.tavares/public/iltbi/rxp2p-cycle/p2p-cycle-env/lib/python3.9/site-packages/requests/adapters.py", line 519, in send
    raise ConnectionError(e, request=request)
requests.exceptions.ConnectionError: HTTPConnectionPool(host='localhost', port=8097): Max retries exceeded with url: /env/main (Caused by NewConnectionError('<urllib3.connection.HTTPConnection object at 0x7f3324e398e0>: Failed to establish a new connection: [Errno 111] Connection refused'))
[Errno 111] Connection refused
on_close() takes 1 positional argument but 3 were given
wandb: Currently logged in as: otavares. Use `wandb login --relogin` to force relogin
wandb: wandb version 0.17.0 is available!  To upgrade, please run:
wandb:  $ pip install wandb --upgrade
wandb: Tracking run with wandb version 0.16.6
wandb: Run data is saved locally in /home/otto.tavares/public/iltbi/rxp2p-cycle/wandb/run-20240510_100527-cycle_ntb_test_1_sort_7
wandb: Run `wandb offline` to turn off syncing.
wandb: Syncing run test_1_sort_7
wandb: ‚≠êÔ∏è View project at https://wandb.ai/otavares/cycle_shenzhen_ntb_santacasa
wandb: üöÄ View run at https://wandb.ai/otavares/cycle_shenzhen_ntb_santacasa/runs/cycle_ntb_test_1_sort_7
/home/otto.tavares/public/iltbi/rxp2p-cycle/p2p-cycle-env/lib/python3.9/site-packages/torch/optim/lr_scheduler.py:143: UserWarning: Detected call of `lr_scheduler.step()` before `optimizer.step()`. In PyTorch 1.1.0 and later, you should call them in the opposite order: `optimizer.step()` before `lr_scheduler.step()`.  Failure to do this will result in PyTorch skipping the first value of the learning rate schedule. See more details at https://pytorch.org/docs/stable/optim.html#how-to-adjust-learning-rate
  warnings.warn("Detected call of `lr_scheduler.step()` before `optimizer.step()`. "
/home/otto.tavares/public/iltbi/rxp2p-cycle/p2p-cycle-env/lib/python3.9/site-packages/torch/utils/data/dataloader.py:558: UserWarning: This DataLoader will create 4 worker processes in total. Our suggested max number of worker in current system is 1, which is smaller than what this DataLoader is going to create. Please be aware that excessive worker creation might get DataLoader running slow or even freeze, lower the worker number to avoid potential slowness/freeze if necessary.
  warnings.warn(_create_warning_msg(
slurmstepd: error: *** JOB 2240 ON caloba79 CANCELLED AT 2024-05-10T10:25:58 ***
