  0%|          | 0/9 [00:00<?, ?it/s]100%|‚ñà‚ñà‚ñà‚ñà‚ñà‚ñà‚ñà‚ñà‚ñà‚ñà| 9/9 [00:00<00:00, 1276.24it/s]
  0%|          | 0/9 [00:00<?, ?it/s]100%|‚ñà‚ñà‚ñà‚ñà‚ñà‚ñà‚ñà‚ñà‚ñà‚ñà| 9/9 [00:00<00:00, 17260.51it/s]
  0%|          | 0/9 [00:00<?, ?it/s]100%|‚ñà‚ñà‚ñà‚ñà‚ñà‚ñà‚ñà‚ñà‚ñà‚ñà| 9/9 [00:00<00:00, 17508.69it/s]
  0%|          | 0/9 [00:00<?, ?it/s]100%|‚ñà‚ñà‚ñà‚ñà‚ñà‚ñà‚ñà‚ñà‚ñà‚ñà| 9/9 [00:00<00:00, 18531.53it/s]
  0%|          | 0/9 [00:00<?, ?it/s]100%|‚ñà‚ñà‚ñà‚ñà‚ñà‚ñà‚ñà‚ñà‚ñà‚ñà| 9/9 [00:00<00:00, 19488.25it/s]
  0%|          | 0/9 [00:00<?, ?it/s]100%|‚ñà‚ñà‚ñà‚ñà‚ñà‚ñà‚ñà‚ñà‚ñà‚ñà| 9/9 [00:00<00:00, 19983.45it/s]
  0%|          | 0/9 [00:00<?, ?it/s]100%|‚ñà‚ñà‚ñà‚ñà‚ñà‚ñà‚ñà‚ñà‚ñà‚ñà| 9/9 [00:00<00:00, 19378.20it/s]
  0%|          | 0/9 [00:00<?, ?it/s]100%|‚ñà‚ñà‚ñà‚ñà‚ñà‚ñà‚ñà‚ñà‚ñà‚ñà| 9/9 [00:00<00:00, 19548.80it/s]
  0%|          | 0/9 [00:00<?, ?it/s]100%|‚ñà‚ñà‚ñà‚ñà‚ñà‚ñà‚ñà‚ñà‚ñà‚ñà| 9/9 [00:00<00:00, 19846.86it/s]
  0%|          | 0/9 [00:00<?, ?it/s]100%|‚ñà‚ñà‚ñà‚ñà‚ñà‚ñà‚ñà‚ñà‚ñà‚ñà| 9/9 [00:00<00:00, 19826.02it/s]
/home/otto.tavares/public/iltbi/rxp2p-cycle/p2p-cycle-env/lib/python3.9/site-packages/torch/utils/data/dataloader.py:558: UserWarning: This DataLoader will create 4 worker processes in total. Our suggested max number of worker in current system is 1, which is smaller than what this DataLoader is going to create. Please be aware that excessive worker creation might get DataLoader running slow or even freeze, lower the worker number to avoid potential slowness/freeze if necessary.
  warnings.warn(_create_warning_msg(
  0%|          | 0/9 [00:00<?, ?it/s]100%|‚ñà‚ñà‚ñà‚ñà‚ñà‚ñà‚ñà‚ñà‚ñà‚ñà| 9/9 [00:00<00:00, 16717.78it/s]
  0%|          | 0/9 [00:00<?, ?it/s]100%|‚ñà‚ñà‚ñà‚ñà‚ñà‚ñà‚ñà‚ñà‚ñà‚ñà| 9/9 [00:00<00:00, 19308.82it/s]
  0%|          | 0/9 [00:00<?, ?it/s]100%|‚ñà‚ñà‚ñà‚ñà‚ñà‚ñà‚ñà‚ñà‚ñà‚ñà| 9/9 [00:00<00:00, 18969.21it/s]
  0%|          | 0/9 [00:00<?, ?it/s]100%|‚ñà‚ñà‚ñà‚ñà‚ñà‚ñà‚ñà‚ñà‚ñà‚ñà| 9/9 [00:00<00:00, 18789.81it/s]
  0%|          | 0/9 [00:00<?, ?it/s]100%|‚ñà‚ñà‚ñà‚ñà‚ñà‚ñà‚ñà‚ñà‚ñà‚ñà| 9/9 [00:00<00:00, 20251.47it/s]
  0%|          | 0/9 [00:00<?, ?it/s]100%|‚ñà‚ñà‚ñà‚ñà‚ñà‚ñà‚ñà‚ñà‚ñà‚ñà| 9/9 [00:00<00:00, 19508.39it/s]
  0%|          | 0/9 [00:00<?, ?it/s]100%|‚ñà‚ñà‚ñà‚ñà‚ñà‚ñà‚ñà‚ñà‚ñà‚ñà| 9/9 [00:00<00:00, 20316.87it/s]
  0%|          | 0/9 [00:00<?, ?it/s]100%|‚ñà‚ñà‚ñà‚ñà‚ñà‚ñà‚ñà‚ñà‚ñà‚ñà| 9/9 [00:00<00:00, 18192.16it/s]
  0%|          | 0/9 [00:00<?, ?it/s]100%|‚ñà‚ñà‚ñà‚ñà‚ñà‚ñà‚ñà‚ñà‚ñà‚ñà| 9/9 [00:00<00:00, 20240.61it/s]
  0%|          | 0/9 [00:00<?, ?it/s]100%|‚ñà‚ñà‚ñà‚ñà‚ñà‚ñà‚ñà‚ñà‚ñà‚ñà| 9/9 [00:00<00:00, 19142.36it/s]
/home/otto.tavares/public/iltbi/rxp2p-cycle/p2p-cycle-env/lib/python3.9/site-packages/torch/utils/data/dataloader.py:558: UserWarning: This DataLoader will create 4 worker processes in total. Our suggested max number of worker in current system is 1, which is smaller than what this DataLoader is going to create. Please be aware that excessive worker creation might get DataLoader running slow or even freeze, lower the worker number to avoid potential slowness/freeze if necessary.
  warnings.warn(_create_warning_msg(
Setting up a new session...
Traceback (most recent call last):
  File "/home/otto.tavares/public/iltbi/rxp2p-cycle/p2p-cycle-env/lib/python3.9/site-packages/urllib3/connection.py", line 198, in _new_conn
    sock = connection.create_connection(
  File "/home/otto.tavares/public/iltbi/rxp2p-cycle/p2p-cycle-env/lib/python3.9/site-packages/urllib3/util/connection.py", line 85, in create_connection
    raise err
  File "/home/otto.tavares/public/iltbi/rxp2p-cycle/p2p-cycle-env/lib/python3.9/site-packages/urllib3/util/connection.py", line 73, in create_connection
    sock.connect(sa)
ConnectionRefusedError: [Errno 111] Connection refused

The above exception was the direct cause of the following exception:

Traceback (most recent call last):
  File "/home/otto.tavares/public/iltbi/rxp2p-cycle/p2p-cycle-env/lib/python3.9/site-packages/urllib3/connectionpool.py", line 793, in urlopen
    response = self._make_request(
  File "/home/otto.tavares/public/iltbi/rxp2p-cycle/p2p-cycle-env/lib/python3.9/site-packages/urllib3/connectionpool.py", line 496, in _make_request
    conn.request(
  File "/home/otto.tavares/public/iltbi/rxp2p-cycle/p2p-cycle-env/lib/python3.9/site-packages/urllib3/connection.py", line 400, in request
    self.endheaders()
  File "/usr/lib/python3.9/http/client.py", line 1250, in endheaders
    self._send_output(message_body, encode_chunked=encode_chunked)
  File "/usr/lib/python3.9/http/client.py", line 1010, in _send_output
    self.send(msg)
  File "/usr/lib/python3.9/http/client.py", line 950, in send
    self.connect()
  File "/home/otto.tavares/public/iltbi/rxp2p-cycle/p2p-cycle-env/lib/python3.9/site-packages/urllib3/connection.py", line 238, in connect
    self.sock = self._new_conn()
  File "/home/otto.tavares/public/iltbi/rxp2p-cycle/p2p-cycle-env/lib/python3.9/site-packages/urllib3/connection.py", line 213, in _new_conn
    raise NewConnectionError(
urllib3.exceptions.NewConnectionError: <urllib3.connection.HTTPConnection object at 0x7f2129f898b0>: Failed to establish a new connection: [Errno 111] Connection refused

The above exception was the direct cause of the following exception:

Traceback (most recent call last):
  File "/home/otto.tavares/public/iltbi/rxp2p-cycle/p2p-cycle-env/lib/python3.9/site-packages/requests/adapters.py", line 486, in send
    resp = conn.urlopen(
  File "/home/otto.tavares/public/iltbi/rxp2p-cycle/p2p-cycle-env/lib/python3.9/site-packages/urllib3/connectionpool.py", line 847, in urlopen
    retries = retries.increment(
  File "/home/otto.tavares/public/iltbi/rxp2p-cycle/p2p-cycle-env/lib/python3.9/site-packages/urllib3/util/retry.py", line 515, in increment
    raise MaxRetryError(_pool, url, reason) from reason  # type: ignore[arg-type]
urllib3.exceptions.MaxRetryError: HTTPConnectionPool(host='localhost', port=8097): Max retries exceeded with url: /env/main (Caused by NewConnectionError('<urllib3.connection.HTTPConnection object at 0x7f2129f898b0>: Failed to establish a new connection: [Errno 111] Connection refused'))

During handling of the above exception, another exception occurred:

Traceback (most recent call last):
  File "/home/otto.tavares/public/iltbi/rxp2p-cycle/p2p-cycle-env/lib/python3.9/site-packages/visdom/__init__.py", line 756, in _send
    return self._handle_post(
  File "/home/otto.tavares/public/iltbi/rxp2p-cycle/p2p-cycle-env/lib/python3.9/site-packages/visdom/__init__.py", line 720, in _handle_post
    r = self.session.post(url, data=data)
  File "/home/otto.tavares/public/iltbi/rxp2p-cycle/p2p-cycle-env/lib/python3.9/site-packages/requests/sessions.py", line 637, in post
    return self.request("POST", url, data=data, json=json, **kwargs)
  File "/home/otto.tavares/public/iltbi/rxp2p-cycle/p2p-cycle-env/lib/python3.9/site-packages/requests/sessions.py", line 589, in request
    resp = self.send(prep, **send_kwargs)
  File "/home/otto.tavares/public/iltbi/rxp2p-cycle/p2p-cycle-env/lib/python3.9/site-packages/requests/sessions.py", line 703, in send
    r = adapter.send(request, **kwargs)
  File "/home/otto.tavares/public/iltbi/rxp2p-cycle/p2p-cycle-env/lib/python3.9/site-packages/requests/adapters.py", line 519, in send
    raise ConnectionError(e, request=request)
requests.exceptions.ConnectionError: HTTPConnectionPool(host='localhost', port=8097): Max retries exceeded with url: /env/main (Caused by NewConnectionError('<urllib3.connection.HTTPConnection object at 0x7f2129f898b0>: Failed to establish a new connection: [Errno 111] Connection refused'))
[Errno 111] Connection refused
on_close() takes 1 positional argument but 3 were given
wandb: Currently logged in as: otavares. Use `wandb login --relogin` to force relogin
wandb: Tracking run with wandb version 0.16.6
wandb: Run data is saved locally in /home/otto.tavares/public/iltbi/rxp2p-cycle/wandb/run-20240506_174456-cycle_ntb_test_0_sort_0
wandb: Run `wandb offline` to turn off syncing.
wandb: Syncing run test_0_sort_0
wandb: ‚≠êÔ∏è View project at https://wandb.ai/otavares/cycle_shenzhen_ntb_santacasa
wandb: üöÄ View run at https://wandb.ai/otavares/cycle_shenzhen_ntb_santacasa/runs/cycle_ntb_test_0_sort_0
/home/otto.tavares/public/iltbi/rxp2p-cycle/p2p-cycle-env/lib/python3.9/site-packages/torch/optim/lr_scheduler.py:143: UserWarning: Detected call of `lr_scheduler.step()` before `optimizer.step()`. In PyTorch 1.1.0 and later, you should call them in the opposite order: `optimizer.step()` before `lr_scheduler.step()`.  Failure to do this will result in PyTorch skipping the first value of the learning rate schedule. See more details at https://pytorch.org/docs/stable/optim.html#how-to-adjust-learning-rate
  warnings.warn("Detected call of `lr_scheduler.step()` before `optimizer.step()`. "
/home/otto.tavares/public/iltbi/rxp2p-cycle/p2p-cycle-env/lib/python3.9/site-packages/torch/utils/data/dataloader.py:558: UserWarning: This DataLoader will create 4 worker processes in total. Our suggested max number of worker in current system is 1, which is smaller than what this DataLoader is going to create. Please be aware that excessive worker creation might get DataLoader running slow or even freeze, lower the worker number to avoid potential slowness/freeze if necessary.
  warnings.warn(_create_warning_msg(
wandb: ERROR Error uploading "/home/otto.tavares/.local/share/wandb/artifacts/staging/tmpwvqav8a6": PermissionError, [Errno 13] Permission denied: '/home/otto.tavares/.cache/wandb/artifacts/obj/md5/48/f59a5bae8bcb2107c759ecf11a4971'
wandb: ERROR Uploading artifact file failed. Artifact won't be committed.
wandb: ERROR Error uploading "/home/otto.tavares/.local/share/wandb/artifacts/staging/tmp1aw3dqud": PermissionError, [Errno 13] Permission denied: '/home/otto.tavares/.cache/wandb/artifacts/obj/md5/48/f59a5bae8bcb2107c759ecf11a4971'
wandb: ERROR Uploading artifact file failed. Artifact won't be committed.
wandb: ERROR Error uploading "/home/otto.tavares/.local/share/wandb/artifacts/staging/tmptz694xgt": PermissionError, [Errno 13] Permission denied: '/home/otto.tavares/.cache/wandb/artifacts/obj/md5/aa/45da215aa96259f87e238590a71842'
wandb: ERROR Uploading artifact file failed. Artifact won't be committed.
wandb: - 179.566 MB of 179.708 MB uploaded (0.120 MB deduped)wandb: \ 179.566 MB of 179.708 MB uploaded (0.120 MB deduped)wandb: | 179.566 MB of 179.708 MB uploaded (0.120 MB deduped)wandb: / 179.566 MB of 179.708 MB uploaded (0.120 MB deduped)wandb: - 181.286 MB of 181.698 MB uploaded (0.120 MB deduped)wandb: \ 181.556 MB of 181.698 MB uploaded (0.120 MB deduped)wandb: | 181.556 MB of 181.698 MB uploaded (0.120 MB deduped)wandb: 
wandb: Run history:
wandb:                D_A ‚ñÖ‚ñà‚ñÖ‚ñÅ‚ñÉ‚ñÉ‚ñÜ‚ñá‚ñÑ‚ñÇ‚ñÉ‚ñÇ‚ñÖ‚ñÇ‚ñÇ‚ñÇ‚ñÜ‚ñÉ‚ñÜ‚ñÇ‚ñÅ‚ñÜ‚ñÇ‚ñÖ‚ñÇ‚ñÜ‚ñÇ‚ñÉ‚ñÇ‚ñÇ‚ñÇ‚ñÅ‚ñÅ‚ñÅ‚ñÅ‚ñÅ‚ñÅ‚ñÇ‚ñÅ‚ñÅ
wandb:            D_A_val ‚ñÇ‚ñÇ‚ñÇ‚ñÇ‚ñÉ‚ñÇ‚ñÉ‚ñÉ‚ñÇ‚ñÇ‚ñÉ‚ñÉ‚ñÇ‚ñÇ‚ñÇ‚ñÇ‚ñÇ‚ñÇ‚ñÉ‚ñÇ‚ñÉ‚ñÇ‚ñÅ‚ñÇ‚ñÅ‚ñÅ‚ñÅ‚ñÇ‚ñÅ‚ñÉ‚ñÉ‚ñÅ‚ñÅ‚ñÑ‚ñÖ‚ñÇ‚ñÇ‚ñÉ‚ñà‚ñÇ
wandb:                D_B ‚ñÑ‚ñÜ‚ñÖ‚ñÑ‚ñÉ‚ñÑ‚ñÑ‚ñÖ‚ñÉ‚ñÉ‚ñÑ‚ñÉ‚ñÖ‚ñà‚ñá‚ñÇ‚ñÉ‚ñÑ‚ñÉ‚ñÇ‚ñÑ‚ñÑ‚ñÇ‚ñÖ‚ñÉ‚ñÇ‚ñÇ‚ñÅ‚ñÇ‚ñÅ‚ñÇ‚ñÇ‚ñÇ‚ñÅ‚ñÇ‚ñÅ‚ñÇ‚ñÅ‚ñÅ‚ñÅ
wandb:            D_B_val ‚ñÅ‚ñÇ‚ñÇ‚ñÅ‚ñÉ‚ñÉ‚ñÇ‚ñÇ‚ñÅ‚ñÉ‚ñÑ‚ñÇ‚ñÅ‚ñÑ‚ñÇ‚ñÑ‚ñÅ‚ñÅ‚ñÅ‚ñÇ‚ñÇ‚ñÅ‚ñÅ‚ñÅ‚ñÅ‚ñÇ‚ñÅ‚ñÅ‚ñÉ‚ñÉ‚ñÉ‚ñÅ‚ñÇ‚ñÑ‚ñÇ‚ñÇ‚ñÅ‚ñà‚ñÅ‚ñÅ
wandb:                G_A ‚ñÑ‚ñÑ‚ñÅ‚ñÅ‚ñÇ‚ñÇ‚ñÇ‚ñÇ‚ñÉ‚ñà‚ñÇ‚ñÖ‚ñÖ‚ñÇ‚ñÜ‚ñÖ‚ñÇ‚ñÉ‚ñÇ‚ñÉ‚ñÇ‚ñÜ‚ñÖ‚ñÉ‚ñÑ‚ñÉ‚ñÑ‚ñÇ‚ñÉ‚ñÉ‚ñÉ‚ñÉ‚ñÉ‚ñÑ‚ñÖ‚ñÖ‚ñÑ‚ñÑ‚ñÖ‚ñÉ
wandb:            G_A_val ‚ñÇ‚ñÇ‚ñÇ‚ñÅ‚ñÇ‚ñÇ‚ñÅ‚ñÅ‚ñÇ‚ñÉ‚ñÖ‚ñÉ‚ñÇ‚ñÅ‚ñÖ‚ñÅ‚ñÉ‚ñÉ‚ñÅ‚ñÅ‚ñÅ‚ñÇ‚ñÇ‚ñÑ‚ñÉ‚ñÉ‚ñÉ‚ñÑ‚ñÉ‚ñÑ‚ñÉ‚ñÉ‚ñÑ‚ñÑ‚ñÜ‚ñÉ‚ñÖ‚ñà‚ñá‚ñà
wandb:                G_B ‚ñÑ‚ñÇ‚ñÇ‚ñÅ‚ñÖ‚ñÇ‚ñÉ‚ñÅ‚ñÇ‚ñÑ‚ñÇ‚ñÑ‚ñÇ‚ñÅ‚ñÅ‚ñÑ‚ñÇ‚ñÑ‚ñÑ‚ñÉ‚ñÉ‚ñÇ‚ñÖ‚ñÉ‚ñÑ‚ñÇ‚ñÑ‚ñÑ‚ñÖ‚ñÑ‚ñÜ‚ñÉ‚ñÑ‚ñÉ‚ñà‚ñÑ‚ñÉ‚ñÜ‚ñÑ‚ñÑ
wandb:            G_B_val ‚ñÉ‚ñÉ‚ñÉ‚ñÑ‚ñÖ‚ñÇ‚ñÑ‚ñÇ‚ñÉ‚ñÅ‚ñÅ‚ñÖ‚ñÉ‚ñÅ‚ñÑ‚ñÑ‚ñÖ‚ñÑ‚ñÑ‚ñÉ‚ñà‚ñÖ‚ñÑ‚ñÉ‚ñÖ‚ñÑ‚ñÑ‚ñÖ‚ñÅ‚ñÅ‚ñÉ‚ñÖ‚ñÉ‚ñÑ‚ñÖ‚ñÜ‚ñÖ‚ñÖ‚ñÑ‚ñÜ
wandb:     KL_realA_fakeA ‚ñÇ‚ñÅ‚ñÅ‚ñÜ‚ñÇ‚ñÅ‚ñÇ‚ñÅ‚ñÇ‚ñÑ‚ñÉ‚ñÉ‚ñÅ‚ñÉ‚ñÉ‚ñÇ‚ñÇ‚ñÇ‚ñÅ‚ñÅ‚ñÇ‚ñà‚ñÉ‚ñÉ‚ñÇ‚ñÅ‚ñÇ‚ñÖ‚ñÇ‚ñÅ‚ñÇ‚ñÑ‚ñÅ‚ñÉ‚ñÇ‚ñÅ‚ñÉ‚ñÉ‚ñÅ‚ñÑ
wandb: KL_realA_fakeA_val ‚ñÉ‚ñÇ‚ñÉ‚ñÇ‚ñÇ‚ñÅ‚ñÅ‚ñÉ‚ñÉ‚ñÉ‚ñÇ‚ñÑ‚ñÇ‚ñÇ‚ñÑ‚ñÉ‚ñÅ‚ñÉ‚ñÇ‚ñÑ‚ñÅ‚ñÇ‚ñÅ‚ñÇ‚ñÉ‚ñÅ‚ñÅ‚ñÉ‚ñà‚ñÅ‚ñÉ‚ñÅ‚ñÑ‚ñÜ‚ñÉ‚ñÇ‚ñÅ‚ñÉ‚ñÅ‚ñÅ
wandb:     KL_realB_fakeB ‚ñÇ‚ñÇ‚ñÇ‚ñÅ‚ñÇ‚ñÅ‚ñÇ‚ñÅ‚ñà‚ñÇ‚ñà‚ñÇ‚ñÅ‚ñÇ‚ñÅ‚ñÅ‚ñÇ‚ñÇ‚ñÅ‚ñÇ‚ñÑ‚ñÇ‚ñÇ‚ñÇ‚ñÇ‚ñÅ‚ñÇ‚ñÑ‚ñÅ‚ñÅ‚ñÅ‚ñÉ‚ñÅ‚ñÇ‚ñÅ‚ñÅ‚ñÉ‚ñÇ‚ñÅ‚ñÅ
wandb: KL_realB_fakeB_val ‚ñÅ‚ñÅ‚ñÑ‚ñÅ‚ñÅ‚ñÇ‚ñÅ‚ñà‚ñÉ‚ñÅ‚ñÅ‚ñÜ‚ñÅ‚ñÅ‚ñÇ‚ñÅ‚ñÅ‚ñÅ‚ñÅ‚ñÇ‚ñÅ‚ñÅ‚ñÅ‚ñÅ‚ñÅ‚ñÅ‚ñÅ‚ñÇ‚ñÇ‚ñÇ‚ñÇ‚ñÇ‚ñÉ‚ñÇ‚ñÉ‚ñÅ‚ñÅ‚ñÅ‚ñÅ‚ñÅ
wandb:            cycle_A ‚ñÖ‚ñà‚ñÖ‚ñá‚ñÉ‚ñÖ‚ñÑ‚ñÑ‚ñÜ‚ñà‚ñÇ‚ñÑ‚ñÑ‚ñÇ‚ñÑ‚ñÉ‚ñÉ‚ñÉ‚ñÇ‚ñÑ‚ñÉ‚ñÇ‚ñÑ‚ñÑ‚ñÑ‚ñÇ‚ñÅ‚ñÜ‚ñÉ‚ñÉ‚ñÉ‚ñÑ‚ñÅ‚ñÅ‚ñÑ‚ñÉ‚ñÅ‚ñÅ‚ñÉ‚ñÅ
wandb:        cycle_A_val ‚ñÖ‚ñà‚ñÉ‚ñá‚ñÜ‚ñÖ‚ñÑ‚ñÇ‚ñÇ‚ñÅ‚ñÖ‚ñÖ‚ñÑ‚ñÉ‚ñÜ‚ñÇ‚ñÑ‚ñÜ‚ñÇ‚ñÅ‚ñÖ‚ñÉ‚ñÑ‚ñÖ‚ñÅ‚ñÉ‚ñÉ‚ñÉ‚ñÑ‚ñÅ‚ñÅ‚ñÉ‚ñÅ‚ñÑ‚ñÅ‚ñÉ‚ñÑ‚ñÅ‚ñÉ‚ñÉ
wandb:            cycle_B ‚ñÜ‚ñá‚ñÜ‚ñÖ‚ñÜ‚ñÖ‚ñÜ‚ñÉ‚ñÑ‚ñÜ‚ñÇ‚ñÜ‚ñÉ‚ñÇ‚ñÇ‚ñÇ‚ñÉ‚ñá‚ñÉ‚ñÇ‚ñÇ‚ñÉ‚ñÉ‚ñÉ‚ñÇ‚ñÉ‚ñÇ‚ñà‚ñÉ‚ñÇ‚ñÇ‚ñÇ‚ñÉ‚ñÇ‚ñÉ‚ñÇ‚ñÅ‚ñÅ‚ñÅ‚ñÇ
wandb:        cycle_B_val ‚ñÖ‚ñÜ‚ñá‚ñÇ‚ñÇ‚ñÇ‚ñÉ‚ñÇ‚ñÇ‚ñÅ‚ñÇ‚ñÉ‚ñÑ‚ñÇ‚ñÑ‚ñÇ‚ñÇ‚ñÇ‚ñÅ‚ñÇ‚ñÇ‚ñÇ‚ñÉ‚ñÇ‚ñÇ‚ñÇ‚ñÅ‚ñÇ‚ñÇ‚ñÇ‚ñÇ‚ñÅ‚ñÇ‚ñÇ‚ñà‚ñÇ‚ñÅ‚ñÅ‚ñÅ‚ñÅ
wandb:              idt_A ‚ñÑ‚ñà‚ñÑ‚ñÑ‚ñÖ‚ñÉ‚ñÉ‚ñÉ‚ñÇ‚ñÉ‚ñÉ‚ñÖ‚ñÇ‚ñÇ‚ñÇ‚ñÇ‚ñÇ‚ñÖ‚ñÇ‚ñÇ‚ñÇ‚ñÉ‚ñÉ‚ñÇ‚ñÇ‚ñÇ‚ñÇ‚ñÇ‚ñÅ‚ñÅ‚ñÇ‚ñÇ‚ñÇ‚ñÅ‚ñÅ‚ñÇ‚ñÅ‚ñÅ‚ñÅ‚ñÇ
wandb:          idt_A_val ‚ñÜ‚ñÖ‚ñá‚ñÉ‚ñÉ‚ñÉ‚ñÉ‚ñÇ‚ñÇ‚ñÇ‚ñÇ‚ñÑ‚ñÉ‚ñÇ‚ñÉ‚ñÇ‚ñÇ‚ñÇ‚ñÅ‚ñÇ‚ñÇ‚ñÇ‚ñÇ‚ñÇ‚ñÇ‚ñÇ‚ñÅ‚ñÅ‚ñÇ‚ñÅ‚ñÅ‚ñÅ‚ñÅ‚ñÅ‚ñà‚ñÅ‚ñÅ‚ñÅ‚ñÅ‚ñÅ
wandb:              idt_B ‚ñÖ‚ñà‚ñÑ‚ñá‚ñÉ‚ñÖ‚ñÑ‚ñÑ‚ñÑ‚ñÑ‚ñÇ‚ñÑ‚ñÑ‚ñÇ‚ñÑ‚ñÉ‚ñÉ‚ñÉ‚ñÉ‚ñÉ‚ñÇ‚ñÉ‚ñÑ‚ñá‚ñÑ‚ñÉ‚ñÅ‚ñÖ‚ñÉ‚ñÉ‚ñÉ‚ñÉ‚ñÇ‚ñÅ‚ñÉ‚ñÉ‚ñÅ‚ñÅ‚ñÇ‚ñÅ
wandb:          idt_B_val ‚ñÑ‚ñÑ‚ñÇ‚ñà‚ñÉ‚ñÑ‚ñÑ‚ñÇ‚ñÅ‚ñÅ‚ñÉ‚ñÉ‚ñÉ‚ñÇ‚ñÇ‚ñÅ‚ñÉ‚ñÑ‚ñÇ‚ñÅ‚ñÉ‚ñÇ‚ñÉ‚ñÑ‚ñÅ‚ñÇ‚ñÇ‚ñÉ‚ñÇ‚ñÅ‚ñÅ‚ñÇ‚ñÅ‚ñÉ‚ñÅ‚ñÇ‚ñÑ‚ñÅ‚ñÉ‚ñÇ
wandb: 
wandb: Run summary:
wandb:                D_A 0.0266
wandb:            D_A_val 0.43661
wandb:                D_B 0.01132
wandb:            D_B_val 0.34735
wandb:                G_A 0.58862
wandb:            G_A_val 1.73508
wandb:                G_B 0.74826
wandb:            G_B_val 1.01434
wandb:     KL_realA_fakeA 0.48065
wandb: KL_realA_fakeA_val 0.13322
wandb:     KL_realB_fakeB 0.08001
wandb: KL_realB_fakeB_val 0.1293
wandb:            cycle_A 0.32394
wandb:        cycle_A_val 0.33799
wandb:            cycle_B 0.40061
wandb:        cycle_B_val 0.4618
wandb:              idt_A 0.1305
wandb:          idt_A_val 0.12267
wandb:              idt_B 0.09555
wandb:          idt_B_val 0.09183
wandb: 
wandb: üöÄ View run test_0_sort_0 at: https://wandb.ai/otavares/cycle_shenzhen_ntb_santacasa/runs/cycle_ntb_test_0_sort_0
wandb: ‚≠êÔ∏è View project at: https://wandb.ai/otavares/cycle_shenzhen_ntb_santacasa
wandb: Synced 6 W&B file(s), 1170 media file(s), 1173 artifact file(s) and 1 other file(s)
wandb: Find logs at: ./wandb/run-20240506_174456-cycle_ntb_test_0_sort_0/logs
