Traceback (most recent call last):
  File "/home/otto.tavares/.local/lib/python3.9/site-packages/pandas/core/indexes/base.py", line 3800, in get_loc
    return self._engine.get_loc(casted_key)
  File "pandas/_libs/index.pyx", line 138, in pandas._libs.index.IndexEngine.get_loc
  File "pandas/_libs/index.pyx", line 165, in pandas._libs.index.IndexEngine.get_loc
  File "pandas/_libs/hashtable_class_helper.pxi", line 5745, in pandas._libs.hashtable.PyObjectHashTable.get_item
  File "pandas/_libs/hashtable_class_helper.pxi", line 5753, in pandas._libs.hashtable.PyObjectHashTable.get_item
KeyError: 'paired_image_path'

The above exception was the direct cause of the following exception:

Traceback (most recent call last):
  File "/home/otto.tavares/public/iltbi/rxpixp2pixcycle/generate_synth.py", line 83, in <module>
    dataset = create_dataset(opt)  # create a dataset given opt.dataset_mode and other options
  File "/home/otto.tavares/public/iltbi/rxpixp2pixcycle/data/__init__.py", line 57, in create_dataset
    data_loader = CustomDatasetDataLoader(opt)
  File "/home/otto.tavares/public/iltbi/rxpixp2pixcycle/data/__init__.py", line 73, in __init__
    self.dataset = dataset_class(opt)
  File "/home/otto.tavares/public/iltbi/rxpixp2pixcycle/data/cyclesantacasaskfold2generator_dataset.py", line 243, in __init__
    print('Generating NTB and TRAIN data: ' + str(len(self.train_ntb['paired_image_path'].tolist())) + ' imgs')
  File "/home/otto.tavares/.local/lib/python3.9/site-packages/pandas/core/frame.py", line 3805, in __getitem__
    indexer = self.columns.get_loc(key)
  File "/home/otto.tavares/.local/lib/python3.9/site-packages/pandas/core/indexes/base.py", line 3802, in get_loc
    raise KeyError(key) from err
KeyError: 'paired_image_path'
